process: 0 added to ready queue at time(seconds): 0
Ready Queue: 0 
process: 0 removed from ready queue at time(seconds): 0
Ready Queue: 
process: 2 added to ready queue at time(seconds): 0
Ready Queue: 2 
process: 6 added to ready queue at time(seconds): 0
Ready Queue: 2 
process: 9 added to ready queue at time(seconds): 0
Ready Queue: 2 6 
process: 5 added to ready queue at time(seconds): 0
Ready Queue: 2 6 
process: 8 added to ready queue at time(seconds): 0
Ready Queue: 2 6 9 
process: 7 added to ready queue at time(seconds): 0
Ready Queue: 2 6 9 
process: 1 added to ready queue at time(seconds): 0
Ready Queue: 2 6 9 5 
process: 3 added to ready queue at time(seconds): 0
Ready Queue: 2 6 9 5 
process: 4 added to ready queue at time(seconds): 0
Ready Queue: 2 6 9 5 8 
process: 2 removed from ready queue at time(seconds): 0.3
Ready Queue: 6 9 5 8 
process: 0 added to ready queue at time(seconds): 0.3
Ready Queue: 6 9 5 8 7 
process: 6 removed from ready queue at time(seconds): 0.6
Ready Queue: 9 5 8 7 
process: 2 added to ready queue at time(seconds): 0.6
Ready Queue: 9 5 8 7 1 
process: 9 removed from ready queue at time(seconds): 0.6
Ready Queue: 5 8 7 1 
process: 6 added to io queue at time(seconds): 0.6
IO Queue: 6 
process: 6 removed from IO queue at time(seconds): 0.6
IO Queue: 
process: 5 removed from ready queue at time(seconds): 0.6
Ready Queue: 8 7 1 3 
process: 9 added to io queue at time(seconds): 0.6
IO Queue: 9 
process: 8 removed from ready queue at time(seconds): 0.6
Ready Queue: 7 1 3 
process: 5 added to io queue at time(seconds): 0.6
IO Queue: 9 
process: 7 removed from ready queue at time(seconds): 0.6
Ready Queue: 1 3 4 
process: 8 added to io queue at time(seconds): 0.6
IO Queue: 9 5 
process: 1 removed from ready queue at time(seconds): 0.6
Ready Queue: 3 4 
process: 7 added to io queue at time(seconds): 0.6
IO Queue: 9 5 
process: 3 removed from ready queue at time(seconds): 0.6
Ready Queue: 4 0 
process: 1 added to io queue at time(seconds): 0.6
IO Queue: 9 5 8 
process: 4 removed from ready queue at time(seconds): 0.9
Ready Queue: 0 
process: 3 added to ready queue at time(seconds): 0.9
Ready Queue: 0 2 
process: 0 removed from ready queue at time(seconds): 1.2
Ready Queue: 2 
process: 4 added to ready queue at time(seconds): 1.2
Ready Queue: 2 3 
process: 2 removed from ready queue at time(seconds): 1.5
Ready Queue: 3 
process: 0 added to ready queue at time(seconds): 1.5
Ready Queue: 3 4 
process: 9 removed from IO queue at time(seconds): 1.6
IO Queue: 5 8 
process: 6 added to ready queue at time(seconds): 1.6
Ready Queue: 3 4 
process: 3 removed from ready queue at time(seconds): 1.8
Ready Queue: 4 0 
process: 2 added to ready queue at time(seconds): 1.8
Ready Queue: 4 0 
process: 4 removed from ready queue at time(seconds): 2.1
Ready Queue: 0 6 
process: 3 added to ready queue at time(seconds): 2.1
Ready Queue: 0 6 
process: 0 removed from ready queue at time(seconds): 2.4
Ready Queue: 6 2 
process: 4 added to ready queue at time(seconds): 2.4
Ready Queue: 6 2 
process: 5 removed from IO queue at time(seconds): 2.6
IO Queue: 8 7 
process: 9 added to ready queue at time(seconds): 2.6
Ready Queue: 6 2 3 
process: 6 removed from ready queue at time(seconds): 2.7
Ready Queue: 2 3 
process: 0 added to ready queue at time(seconds): 2.7
Ready Queue: 2 3 4 
process: 2 removed from ready queue at time(seconds): 3
Ready Queue: 3 4 
process: 6 added to ready queue at time(seconds): 3
Ready Queue: 3 4 9 
process: 3 removed from ready queue at time(seconds): 3.3
Ready Queue: 4 9 
process: 2 added to ready queue at time(seconds): 3.3
Ready Queue: 4 9 0 
process: 4 removed from ready queue at time(seconds): 3.6
Ready Queue: 9 0 
process: 3 added to ready queue at time(seconds): 3.6
Ready Queue: 9 0 6 
process: 8 removed from IO queue at time(seconds): 3.6
IO Queue: 7 
process: 5 added to ready queue at time(seconds): 3.6
Ready Queue: 9 0 6 
process: 9 removed from ready queue at time(seconds): 3.9
Ready Queue: 0 6 2 
process: 4 added to ready queue at time(seconds): 3.9
Ready Queue: 0 6 2 
process: 0 removed from ready queue at time(seconds): 4.2
Ready Queue: 6 2 3 
process: 9 added to ready queue at time(seconds): 4.2
Ready Queue: 6 2 3 
process: 6 removed from ready queue at time(seconds): 4.5
Ready Queue: 2 3 5 
process: 0 added to ready queue at time(seconds): 4.5
Ready Queue: 2 3 5 
process: 7 removed from IO queue at time(seconds): 4.6
IO Queue: 1 
process: 8 added to ready queue at time(seconds): 4.6
Ready Queue: 2 3 5 4 
process: 2 removed from ready queue at time(seconds): 4.8
Ready Queue: 3 5 4 
process: 6 added to ready queue at time(seconds): 4.8
Ready Queue: 3 5 4 9 
process: 3 removed from ready queue at time(seconds): 5.1
Ready Queue: 5 4 9 
process: 2 added to ready queue at time(seconds): 5.1
Ready Queue: 5 4 9 0 
process: 5 removed from ready queue at time(seconds): 5.4
Ready Queue: 4 9 0 
process: 3 added to ready queue at time(seconds): 5.4
Ready Queue: 4 9 0 8 
process: 1 removed from IO queue at time(seconds): 5.6
IO Queue: 
process: 7 added to ready queue at time(seconds): 5.6
Ready Queue: 4 9 0 8 
process: 4 removed from ready queue at time(seconds): 5.7
Ready Queue: 9 0 8 6 
process: 5 added to ready queue at time(seconds): 5.7
Ready Queue: 9 0 8 6 
process: 9 removed from ready queue at time(seconds): 6
Ready Queue: 0 8 6 2 
process: 4 added to ready queue at time(seconds): 6
Ready Queue: 0 8 6 2 
process: 0 removed from ready queue at time(seconds): 6.3
Ready Queue: 8 6 2 3 
process: 9 added to ready queue at time(seconds): 6.3
Ready Queue: 8 6 2 3 
process: 8 removed from ready queue at time(seconds): 6.6
Ready Queue: 6 2 3 7 
process: 0 added to ready queue at time(seconds): 6.6
Ready Queue: 6 2 3 7 
process: 1 added to ready queue at time(seconds): 6.6
Ready Queue: 6 2 3 7 5 
process: 6 removed from ready queue at time(seconds): 6.9
Ready Queue: 2 3 7 5 
process: 8 added to ready queue at time(seconds): 6.9
Ready Queue: 2 3 7 5 4 
process: 2 removed from ready queue at time(seconds): 7.2
Ready Queue: 3 7 5 4 
process: 6 added to ready queue at time(seconds): 7.2
Ready Queue: 3 7 5 4 9 
process: 3 removed from ready queue at time(seconds): 7.5
Ready Queue: 7 5 4 9 
process: 2 added to ready queue at time(seconds): 7.5
Ready Queue: 7 5 4 9 0 
process: 7 removed from ready queue at time(seconds): 7.8
Ready Queue: 5 4 9 0 
process: 3 added to ready queue at time(seconds): 7.8
Ready Queue: 5 4 9 0 1 
process: 5 removed from ready queue at time(seconds): 8.1
Ready Queue: 4 9 0 1 
process: 7 added to ready queue at time(seconds): 8.1
Ready Queue: 4 9 0 1 8 
process: 4 removed from ready queue at time(seconds): 8.4
Ready Queue: 9 0 1 8 
process: 5 added to ready queue at time(seconds): 8.4
Ready Queue: 9 0 1 8 6 
process: 9 removed from ready queue at time(seconds): 8.7
Ready Queue: 0 1 8 6 
process: 4 added to ready queue at time(seconds): 8.7
Ready Queue: 0 1 8 6 2 
process: 0 removed from ready queue at time(seconds): 9
Ready Queue: 1 8 6 2 
process: 9 added to ready queue at time(seconds): 9
Ready Queue: 1 8 6 2 3 
process: 1 removed from ready queue at time(seconds): 9.3
Ready Queue: 8 6 2 3 
process: 0 added to ready queue at time(seconds): 9.3
Ready Queue: 8 6 2 3 7 
process: 8 removed from ready queue at time(seconds): 9.6
Ready Queue: 6 2 3 7 
process: 1 added to ready queue at time(seconds): 9.6
Ready Queue: 6 2 3 7 5 
process: 6 removed from ready queue at time(seconds): 9.9
Ready Queue: 2 3 7 5 
process: 8 added to ready queue at time(seconds): 9.9
Ready Queue: 2 3 7 5 4 
process: 2 removed from ready queue at time(seconds): 10.2
Ready Queue: 3 7 5 4 
process: 6 added to ready queue at time(seconds): 10.2
Ready Queue: 3 7 5 4 9 
process: 3 removed from ready queue at time(seconds): 10.5
Ready Queue: 7 5 4 9 
process: 2 added to ready queue at time(seconds): 10.5
Ready Queue: 7 5 4 9 0 
process: 7 removed from ready queue at time(seconds): 10.8
Ready Queue: 5 4 9 0 
process: 3 added to ready queue at time(seconds): 10.8
Ready Queue: 5 4 9 0 1 
process: 5 removed from ready queue at time(seconds): 11.1
Ready Queue: 4 9 0 1 
process: 7 added to ready queue at time(seconds): 11.1
Ready Queue: 4 9 0 1 8 
process: 4 removed from ready queue at time(seconds): 11.4
Ready Queue: 9 0 1 8 
process: 5 added to ready queue at time(seconds): 11.4
Ready Queue: 9 0 1 8 6 
process: 9 removed from ready queue at time(seconds): 11.7
Ready Queue: 0 1 8 6 
process: 4 added to ready queue at time(seconds): 11.7
Ready Queue: 0 1 8 6 2 
process: 0 removed from ready queue at time(seconds): 12
Ready Queue: 1 8 6 2 
process: 9 added to ready queue at time(seconds): 12
Ready Queue: 1 8 6 2 3 
process: 1 removed from ready queue at time(seconds): 12.3
Ready Queue: 8 6 2 3 
process: 0 added to ready queue at time(seconds): 12.3
Ready Queue: 8 6 2 3 7 
process: 8 removed from ready queue at time(seconds): 12.6
Ready Queue: 6 2 3 7 
process: 1 added to ready queue at time(seconds): 12.6
Ready Queue: 6 2 3 7 5 
process: 6 removed from ready queue at time(seconds): 12.9
Ready Queue: 2 3 7 5 
process: 8 added to ready queue at time(seconds): 12.9
Ready Queue: 2 3 7 5 4 
process: 2 removed from ready queue at time(seconds): 13.2
Ready Queue: 3 7 5 4 
process: 6 added to ready queue at time(seconds): 13.2
Ready Queue: 3 7 5 4 9 
process: 3 removed from ready queue at time(seconds): 13.5
Ready Queue: 7 5 4 9 
process: 2 added to ready queue at time(seconds): 13.5
Ready Queue: 7 5 4 9 0 
process: 7 removed from ready queue at time(seconds): 13.8
Ready Queue: 5 4 9 0 
process: 3 added to ready queue at time(seconds): 13.8
Ready Queue: 5 4 9 0 1 
process: 5 removed from ready queue at time(seconds): 14.1
Ready Queue: 4 9 0 1 
process: 7 added to ready queue at time(seconds): 14.1
Ready Queue: 4 9 0 1 8 
process: 4 removed from ready queue at time(seconds): 14.4
Ready Queue: 9 0 1 8 
process: 5 added to ready queue at time(seconds): 14.4
Ready Queue: 9 0 1 8 6 
process: 9 removed from ready queue at time(seconds): 14.7
Ready Queue: 0 1 8 6 
process: 4 added to ready queue at time(seconds): 14.7
Ready Queue: 0 1 8 6 2 
process: 0 removed from ready queue at time(seconds): 15
Ready Queue: 1 8 6 2 
process: 9 added to ready queue at time(seconds): 15
Ready Queue: 1 8 6 2 3 
process: 1 removed from ready queue at time(seconds): 15.3
Ready Queue: 8 6 2 3 
process: 0 added to ready queue at time(seconds): 15.3
Ready Queue: 8 6 2 3 7 
process: 8 removed from ready queue at time(seconds): 15.6
Ready Queue: 6 2 3 7 
process: 1 added to ready queue at time(seconds): 15.6
Ready Queue: 6 2 3 7 5 
process: 6 removed from ready queue at time(seconds): 15.9
Ready Queue: 2 3 7 5 
process: 8 added to ready queue at time(seconds): 15.9
Ready Queue: 2 3 7 5 4 
process: 2 removed from ready queue at time(seconds): 16.2
Ready Queue: 3 7 5 4 
process: 6 added to ready queue at time(seconds): 16.2
Ready Queue: 3 7 5 4 9 
process: 3 removed from ready queue at time(seconds): 16.5
Ready Queue: 7 5 4 9 
process: 2 added to ready queue at time(seconds): 16.5
Ready Queue: 7 5 4 9 0 
process: 7 removed from ready queue at time(seconds): 16.8
Ready Queue: 5 4 9 0 
process: 3 added to ready queue at time(seconds): 16.8
Ready Queue: 5 4 9 0 1 
process: 5 removed from ready queue at time(seconds): 17.1
Ready Queue: 4 9 0 1 
process: 7 added to ready queue at time(seconds): 17.1
Ready Queue: 4 9 0 1 8 
process: 4 removed from ready queue at time(seconds): 17.4
Ready Queue: 9 0 1 8 
process: 5 added to ready queue at time(seconds): 17.4
Ready Queue: 9 0 1 8 6 
process: 9 removed from ready queue at time(seconds): 17.7
Ready Queue: 0 1 8 6 
process: 4 added to ready queue at time(seconds): 17.7
Ready Queue: 0 1 8 6 2 
process: 0 removed from ready queue at time(seconds): 18
Ready Queue: 1 8 6 2 
process: 9 added to ready queue at time(seconds): 18
Ready Queue: 1 8 6 2 3 
process: 1 removed from ready queue at time(seconds): 18.3
Ready Queue: 8 6 2 3 
process: 0 added to ready queue at time(seconds): 18.3
Ready Queue: 8 6 2 3 7 
process: 8 removed from ready queue at time(seconds): 18.6
Ready Queue: 6 2 3 7 
process: 1 added to ready queue at time(seconds): 18.6
Ready Queue: 6 2 3 7 5 
process: 6 removed from ready queue at time(seconds): 18.9
Ready Queue: 2 3 7 5 
process: 8 added to ready queue at time(seconds): 18.9
Ready Queue: 2 3 7 5 4 
process: 2 removed from ready queue at time(seconds): 19.2
Ready Queue: 3 7 5 4 
process: 6 added to ready queue at time(seconds): 19.2
Ready Queue: 3 7 5 4 9 
process: 3 removed from ready queue at time(seconds): 19.5
Ready Queue: 7 5 4 9 
process: 2 added to ready queue at time(seconds): 19.5
Ready Queue: 7 5 4 9 0 
process: 7 removed from ready queue at time(seconds): 19.8
Ready Queue: 5 4 9 0 
process: 3 added to ready queue at time(seconds): 19.8
Ready Queue: 5 4 9 0 1 
process: 5 removed from ready queue at time(seconds): 20.1
Ready Queue: 4 9 0 1 
process: 7 added to ready queue at time(seconds): 20.1
Ready Queue: 4 9 0 1 8 
process: 4 removed from ready queue at time(seconds): 20.4
Ready Queue: 9 0 1 8 
process: 5 added to ready queue at time(seconds): 20.4
Ready Queue: 9 0 1 8 6 
process: 9 removed from ready queue at time(seconds): 20.7
Ready Queue: 0 1 8 6 
process: 4 added to ready queue at time(seconds): 20.7
Ready Queue: 0 1 8 6 2 
process: 0 removed from ready queue at time(seconds): 21
Ready Queue: 1 8 6 2 
process: 9 added to ready queue at time(seconds): 21
Ready Queue: 1 8 6 2 3 
process: 1 removed from ready queue at time(seconds): 21.3
Ready Queue: 8 6 2 3 
process: 0 added to ready queue at time(seconds): 21.3
Ready Queue: 8 6 2 3 7 
process: 8 removed from ready queue at time(seconds): 21.6
Ready Queue: 6 2 3 7 
process: 1 added to ready queue at time(seconds): 21.6
Ready Queue: 6 2 3 7 5 
process: 6 removed from ready queue at time(seconds): 21.9
Ready Queue: 2 3 7 5 
process: 8 added to ready queue at time(seconds): 21.9
Ready Queue: 2 3 7 5 4 
process: 2 removed from ready queue at time(seconds): 22.2
Ready Queue: 3 7 5 4 
process: 6 added to ready queue at time(seconds): 22.2
Ready Queue: 3 7 5 4 9 
process: 3 removed from ready queue at time(seconds): 22.5
Ready Queue: 7 5 4 9 
process: 2 added to ready queue at time(seconds): 22.5
Ready Queue: 7 5 4 9 0 
process: 7 removed from ready queue at time(seconds): 22.8
Ready Queue: 5 4 9 0 
process: 3 added to ready queue at time(seconds): 22.8
Ready Queue: 5 4 9 0 1 
process: 5 removed from ready queue at time(seconds): 23.1
Ready Queue: 4 9 0 1 
process: 7 added to ready queue at time(seconds): 23.1
Ready Queue: 4 9 0 1 8 
process: 4 removed from ready queue at time(seconds): 23.4
Ready Queue: 9 0 1 8 
process: 5 added to ready queue at time(seconds): 23.4
Ready Queue: 9 0 1 8 6 
process: 9 removed from ready queue at time(seconds): 23.7
Ready Queue: 0 1 8 6 
process: 4 added to ready queue at time(seconds): 23.7
Ready Queue: 0 1 8 6 2 
process: 0 removed from ready queue at time(seconds): 24
Ready Queue: 1 8 6 2 
process: 9 added to ready queue at time(seconds): 24
Ready Queue: 1 8 6 2 3 
process: 1 removed from ready queue at time(seconds): 24.3
Ready Queue: 8 6 2 3 
process: 0 added to ready queue at time(seconds): 24.3
Ready Queue: 8 6 2 3 7 
process: 8 removed from ready queue at time(seconds): 24.6
Ready Queue: 6 2 3 7 
process: 1 added to ready queue at time(seconds): 24.6
Ready Queue: 6 2 3 7 5 
process: 6 removed from ready queue at time(seconds): 24.9
Ready Queue: 2 3 7 5 
process: 8 added to ready queue at time(seconds): 24.9
Ready Queue: 2 3 7 5 4 
process: 2 removed from ready queue at time(seconds): 25.2
Ready Queue: 3 7 5 4 
process: 6 added to ready queue at time(seconds): 25.2
Ready Queue: 3 7 5 4 9 
process: 3 removed from ready queue at time(seconds): 25.5
Ready Queue: 7 5 4 9 
process: 2 added to ready queue at time(seconds): 25.5
Ready Queue: 7 5 4 9 0 
process: 7 removed from ready queue at time(seconds): 25.8
Ready Queue: 5 4 9 0 
process: 3 added to ready queue at time(seconds): 25.8
Ready Queue: 5 4 9 0 1 
process: 5 removed from ready queue at time(seconds): 26.1
Ready Queue: 4 9 0 1 
process: 7 added to ready queue at time(seconds): 26.1
Ready Queue: 4 9 0 1 8 
process: 4 removed from ready queue at time(seconds): 26.4
Ready Queue: 9 0 1 8 
process: 5 added to ready queue at time(seconds): 26.4
Ready Queue: 9 0 1 8 6 
process: 9 removed from ready queue at time(seconds): 26.7
Ready Queue: 0 1 8 6 
process: 4 added to ready queue at time(seconds): 26.7
Ready Queue: 0 1 8 6 2 
process: 0 removed from ready queue at time(seconds): 27
Ready Queue: 1 8 6 2 
process: 9 added to ready queue at time(seconds): 27
Ready Queue: 1 8 6 2 3 
process: 1 removed from ready queue at time(seconds): 27.3
Ready Queue: 8 6 2 3 
process: 0 added to ready queue at time(seconds): 27.3
Ready Queue: 8 6 2 3 7 
process: 8 removed from ready queue at time(seconds): 27.6
Ready Queue: 6 2 3 7 
process: 1 added to ready queue at time(seconds): 27.6
Ready Queue: 6 2 3 7 5 
process: 6 removed from ready queue at time(seconds): 27.9
Ready Queue: 2 3 7 5 
process: 8 added to ready queue at time(seconds): 27.9
Ready Queue: 2 3 7 5 4 
process: 2 removed from ready queue at time(seconds): 28.2
Ready Queue: 3 7 5 4 
process: 6 added to ready queue at time(seconds): 28.2
Ready Queue: 3 7 5 4 9 
process: 3 removed from ready queue at time(seconds): 28.5
Ready Queue: 7 5 4 9 
process: 2 added to ready queue at time(seconds): 28.5
Ready Queue: 7 5 4 9 0 
process: 7 removed from ready queue at time(seconds): 28.8
Ready Queue: 5 4 9 0 
process: 3 added to ready queue at time(seconds): 28.8
Ready Queue: 5 4 9 0 1 
process: 5 removed from ready queue at time(seconds): 29.1
Ready Queue: 4 9 0 1 
process: 7 added to ready queue at time(seconds): 29.1
Ready Queue: 4 9 0 1 8 
process: 4 removed from ready queue at time(seconds): 29.4
Ready Queue: 9 0 1 8 
process: 5 added to ready queue at time(seconds): 29.4
Ready Queue: 9 0 1 8 6 
process: 9 removed from ready queue at time(seconds): 29.7
Ready Queue: 0 1 8 6 
process: 4 added to ready queue at time(seconds): 29.7
Ready Queue: 0 1 8 6 2 
process: 0 removed from ready queue at time(seconds): 30
Ready Queue: 1 8 6 2 
process: 9 added to ready queue at time(seconds): 30
Ready Queue: 1 8 6 2 3 
process: 1 removed from ready queue at time(seconds): 30.3
Ready Queue: 8 6 2 3 
process: 0 added to ready queue at time(seconds): 30.3
Ready Queue: 8 6 2 3 7 
process: 8 removed from ready queue at time(seconds): 30.6
Ready Queue: 6 2 3 7 
process: 1 added to ready queue at time(seconds): 30.6
Ready Queue: 6 2 3 7 5 
process: 6 removed from ready queue at time(seconds): 30.9
Ready Queue: 2 3 7 5 
process: 8 added to ready queue at time(seconds): 30.9
Ready Queue: 2 3 7 5 4 
process: 2 removed from ready queue at time(seconds): 31.2
Ready Queue: 3 7 5 4 
process: 6 added to ready queue at time(seconds): 31.2
Ready Queue: 3 7 5 4 9 
process: 3 removed from ready queue at time(seconds): 31.5
Ready Queue: 7 5 4 9 
process: 2 added to ready queue at time(seconds): 31.5
Ready Queue: 7 5 4 9 0 
process: 7 removed from ready queue at time(seconds): 31.8
Ready Queue: 5 4 9 0 
process: 3 added to ready queue at time(seconds): 31.8
Ready Queue: 5 4 9 0 1 
process: 5 removed from ready queue at time(seconds): 32.1
Ready Queue: 4 9 0 1 
process: 7 added to ready queue at time(seconds): 32.1
Ready Queue: 4 9 0 1 8 
process: 4 removed from ready queue at time(seconds): 32.4
Ready Queue: 9 0 1 8 
process: 5 added to ready queue at time(seconds): 32.4
Ready Queue: 9 0 1 8 6 
process: 9 removed from ready queue at time(seconds): 32.7
Ready Queue: 0 1 8 6 
process: 4 added to ready queue at time(seconds): 32.7
Ready Queue: 0 1 8 6 2 
process: 0 removed from ready queue at time(seconds): 33
Ready Queue: 1 8 6 2 
process: 9 added to ready queue at time(seconds): 33
Ready Queue: 1 8 6 2 3 
process: 1 removed from ready queue at time(seconds): 33.3
Ready Queue: 8 6 2 3 
process: 0 added to ready queue at time(seconds): 33.3
Ready Queue: 8 6 2 3 7 
process: 8 removed from ready queue at time(seconds): 33.6
Ready Queue: 6 2 3 7 
process: 1 added to ready queue at time(seconds): 33.6
Ready Queue: 6 2 3 7 5 
process: 6 removed from ready queue at time(seconds): 33.9
Ready Queue: 2 3 7 5 
process: 8 added to ready queue at time(seconds): 33.9
Ready Queue: 2 3 7 5 4 
process: 2 removed from ready queue at time(seconds): 34.2
Ready Queue: 3 7 5 4 
process: 6 added to ready queue at time(seconds): 34.2
Ready Queue: 3 7 5 4 9 
process: 3 removed from ready queue at time(seconds): 34.5
Ready Queue: 7 5 4 9 
process: 2 added to ready queue at time(seconds): 34.5
Ready Queue: 7 5 4 9 0 
process: 7 removed from ready queue at time(seconds): 34.8
Ready Queue: 5 4 9 0 
process: 3 added to ready queue at time(seconds): 34.8
Ready Queue: 5 4 9 0 1 
process: 5 removed from ready queue at time(seconds): 35.1
Ready Queue: 4 9 0 1 
process: 7 added to ready queue at time(seconds): 35.1
Ready Queue: 4 9 0 1 8 
process: 4 removed from ready queue at time(seconds): 35.4
Ready Queue: 9 0 1 8 
process: 5 added to ready queue at time(seconds): 35.4
Ready Queue: 9 0 1 8 6 
process: 9 removed from ready queue at time(seconds): 35.7
Ready Queue: 0 1 8 6 
process: 4 added to ready queue at time(seconds): 35.7
Ready Queue: 0 1 8 6 2 
process: 0 removed from ready queue at time(seconds): 36
Ready Queue: 1 8 6 2 
process: 9 added to ready queue at time(seconds): 36
Ready Queue: 1 8 6 2 3 
process: 1 removed from ready queue at time(seconds): 36.3
Ready Queue: 8 6 2 3 
process: 0 added to ready queue at time(seconds): 36.3
Ready Queue: 8 6 2 3 7 
process: 8 removed from ready queue at time(seconds): 36.6
Ready Queue: 6 2 3 7 
process: 1 added to ready queue at time(seconds): 36.6
Ready Queue: 6 2 3 7 5 
process: 6 removed from ready queue at time(seconds): 36.9
Ready Queue: 2 3 7 5 
process: 8 added to ready queue at time(seconds): 36.9
Ready Queue: 2 3 7 5 4 
process: 2 removed from ready queue at time(seconds): 37.2
Ready Queue: 3 7 5 4 
process: 6 added to ready queue at time(seconds): 37.2
Ready Queue: 3 7 5 4 9 
process: 3 removed from ready queue at time(seconds): 37.5
Ready Queue: 7 5 4 9 
process: 2 added to ready queue at time(seconds): 37.5
Ready Queue: 7 5 4 9 0 
process: 7 removed from ready queue at time(seconds): 37.8
Ready Queue: 5 4 9 0 
process: 3 added to ready queue at time(seconds): 37.8
Ready Queue: 5 4 9 0 1 
process: 5 removed from ready queue at time(seconds): 38.1
Ready Queue: 4 9 0 1 
process: 7 added to ready queue at time(seconds): 38.1
Ready Queue: 4 9 0 1 8 
process: 4 removed from ready queue at time(seconds): 38.4
Ready Queue: 9 0 1 8 
process: 5 added to ready queue at time(seconds): 38.4
Ready Queue: 9 0 1 8 6 
process: 9 removed from ready queue at time(seconds): 38.7
Ready Queue: 0 1 8 6 
process: 4 added to ready queue at time(seconds): 38.7
Ready Queue: 0 1 8 6 2 
process: 0 removed from ready queue at time(seconds): 39
Ready Queue: 1 8 6 2 
process: 9 added to ready queue at time(seconds): 39
Ready Queue: 1 8 6 2 3 
process: 1 removed from ready queue at time(seconds): 39.3
Ready Queue: 8 6 2 3 
process: 0 added to ready queue at time(seconds): 39.3
Ready Queue: 8 6 2 3 7 
process: 8 removed from ready queue at time(seconds): 39.6
Ready Queue: 6 2 3 7 
process: 1 added to ready queue at time(seconds): 39.6
Ready Queue: 6 2 3 7 5 
process: 6 removed from ready queue at time(seconds): 39.9
Ready Queue: 2 3 7 5 
process: 8 added to ready queue at time(seconds): 39.9
Ready Queue: 2 3 7 5 4 
process: 2 removed from ready queue at time(seconds): 40.2
Ready Queue: 3 7 5 4 
process: 6 added to ready queue at time(seconds): 40.2
Ready Queue: 3 7 5 4 9 
process: 3 removed from ready queue at time(seconds): 40.5
Ready Queue: 7 5 4 9 
process: 2 added to ready queue at time(seconds): 40.5
Ready Queue: 7 5 4 9 0 
process: 7 removed from ready queue at time(seconds): 40.8
Ready Queue: 5 4 9 0 
process: 3 added to ready queue at time(seconds): 40.8
Ready Queue: 5 4 9 0 1 
process: 5 removed from ready queue at time(seconds): 41.1
Ready Queue: 4 9 0 1 
process: 7 added to ready queue at time(seconds): 41.1
Ready Queue: 4 9 0 1 8 
process: 4 removed from ready queue at time(seconds): 41.4
Ready Queue: 9 0 1 8 
process: 5 added to ready queue at time(seconds): 41.4
Ready Queue: 9 0 1 8 6 
process: 9 removed from ready queue at time(seconds): 41.7
Ready Queue: 0 1 8 6 
process: 4 added to ready queue at time(seconds): 41.7
Ready Queue: 0 1 8 6 2 
process: 0 removed from ready queue at time(seconds): 42
Ready Queue: 1 8 6 2 
process: 9 added to ready queue at time(seconds): 42
Ready Queue: 1 8 6 2 3 
process: 1 removed from ready queue at time(seconds): 42.3
Ready Queue: 8 6 2 3 
process: 0 added to ready queue at time(seconds): 42.3
Ready Queue: 8 6 2 3 7 
process: 8 removed from ready queue at time(seconds): 42.6
Ready Queue: 6 2 3 7 
process: 1 added to ready queue at time(seconds): 42.6
Ready Queue: 6 2 3 7 5 
process: 6 removed from ready queue at time(seconds): 42.9
Ready Queue: 2 3 7 5 
process: 8 added to ready queue at time(seconds): 42.9
Ready Queue: 2 3 7 5 4 
process: 2 removed from ready queue at time(seconds): 43.2
Ready Queue: 3 7 5 4 
process: 6 added to ready queue at time(seconds): 43.2
Ready Queue: 3 7 5 4 9 
process: 3 removed from ready queue at time(seconds): 43.5
Ready Queue: 7 5 4 9 
process: 2 added to ready queue at time(seconds): 43.5
Ready Queue: 7 5 4 9 0 
process: 7 removed from ready queue at time(seconds): 43.8
Ready Queue: 5 4 9 0 
process: 3 added to ready queue at time(seconds): 43.8
Ready Queue: 5 4 9 0 1 
process: 5 removed from ready queue at time(seconds): 44.1
Ready Queue: 4 9 0 1 
process: 7 added to ready queue at time(seconds): 44.1
Ready Queue: 4 9 0 1 8 
process: 4 removed from ready queue at time(seconds): 44.4
Ready Queue: 9 0 1 8 
process: 5 added to ready queue at time(seconds): 44.4
Ready Queue: 9 0 1 8 6 
process: 9 removed from ready queue at time(seconds): 44.7
Ready Queue: 0 1 8 6 
process: 4 added to ready queue at time(seconds): 44.7
Ready Queue: 0 1 8 6 2 
process: 0 removed from ready queue at time(seconds): 45
Ready Queue: 1 8 6 2 
process: 9 added to ready queue at time(seconds): 45
Ready Queue: 1 8 6 2 3 
process: 1 removed from ready queue at time(seconds): 45.3
Ready Queue: 8 6 2 3 
process: 0 added to ready queue at time(seconds): 45.3
Ready Queue: 8 6 2 3 7 
process: 8 removed from ready queue at time(seconds): 45.6
Ready Queue: 6 2 3 7 
process: 1 added to ready queue at time(seconds): 45.6
Ready Queue: 6 2 3 7 5 
process: 6 removed from ready queue at time(seconds): 45.9
Ready Queue: 2 3 7 5 
process: 8 added to ready queue at time(seconds): 45.9
Ready Queue: 2 3 7 5 4 
process: 2 removed from ready queue at time(seconds): 46.2
Ready Queue: 3 7 5 4 
process: 6 added to ready queue at time(seconds): 46.2
Ready Queue: 3 7 5 4 9 
process: 3 removed from ready queue at time(seconds): 46.5
Ready Queue: 7 5 4 9 
process: 2 added to ready queue at time(seconds): 46.5
Ready Queue: 7 5 4 9 0 
process: 7 removed from ready queue at time(seconds): 46.8
Ready Queue: 5 4 9 0 
process: 3 added to ready queue at time(seconds): 46.8
Ready Queue: 5 4 9 0 1 
process: 5 removed from ready queue at time(seconds): 47.1
Ready Queue: 4 9 0 1 
process: 7 added to ready queue at time(seconds): 47.1
Ready Queue: 4 9 0 1 8 
process: 4 removed from ready queue at time(seconds): 47.4
Ready Queue: 9 0 1 8 
process: 5 added to ready queue at time(seconds): 47.4
Ready Queue: 9 0 1 8 6 
process: 9 removed from ready queue at time(seconds): 47.7
Ready Queue: 0 1 8 6 
process: 4 added to ready queue at time(seconds): 47.7
Ready Queue: 0 1 8 6 2 
process: 0 removed from ready queue at time(seconds): 48
Ready Queue: 1 8 6 2 
process: 9 added to ready queue at time(seconds): 48
Ready Queue: 1 8 6 2 3 
process: 1 removed from ready queue at time(seconds): 48.3
Ready Queue: 8 6 2 3 
process: 0 added to ready queue at time(seconds): 48.3
Ready Queue: 8 6 2 3 7 
process: 8 removed from ready queue at time(seconds): 48.6
Ready Queue: 6 2 3 7 
process: 1 added to ready queue at time(seconds): 48.6
Ready Queue: 6 2 3 7 5 
process: 6 removed from ready queue at time(seconds): 48.9
Ready Queue: 2 3 7 5 
process: 8 added to ready queue at time(seconds): 48.9
Ready Queue: 2 3 7 5 4 
process: 2 removed from ready queue at time(seconds): 49.2
Ready Queue: 3 7 5 4 
process: 6 added to ready queue at time(seconds): 49.2
Ready Queue: 3 7 5 4 9 
process: 3 removed from ready queue at time(seconds): 49.5
Ready Queue: 7 5 4 9 
process: 2 added to ready queue at time(seconds): 49.5
Ready Queue: 7 5 4 9 0 
process: 7 removed from ready queue at time(seconds): 49.8
Ready Queue: 5 4 9 0 
process: 3 added to ready queue at time(seconds): 49.8
Ready Queue: 5 4 9 0 1 
process: 5 removed from ready queue at time(seconds): 50.1
Ready Queue: 4 9 0 1 
process: 7 added to ready queue at time(seconds): 50.1
Ready Queue: 4 9 0 1 8 
process: 4 removed from ready queue at time(seconds): 50.4
Ready Queue: 9 0 1 8 
process: 5 added to ready queue at time(seconds): 50.4
Ready Queue: 9 0 1 8 6 
process: 9 removed from ready queue at time(seconds): 50.7
Ready Queue: 0 1 8 6 
process: 4 added to ready queue at time(seconds): 50.7
Ready Queue: 0 1 8 6 2 
process: 0 removed from ready queue at time(seconds): 51
Ready Queue: 1 8 6 2 
process: 9 added to ready queue at time(seconds): 51
Ready Queue: 1 8 6 2 3 
process: 1 removed from ready queue at time(seconds): 51.3
Ready Queue: 8 6 2 3 
process: 0 added to ready queue at time(seconds): 51.3
Ready Queue: 8 6 2 3 7 
process: 8 removed from ready queue at time(seconds): 51.6
Ready Queue: 6 2 3 7 
process: 1 added to ready queue at time(seconds): 51.6
Ready Queue: 6 2 3 7 5 
process: 6 removed from ready queue at time(seconds): 51.9
Ready Queue: 2 3 7 5 
process: 8 added to ready queue at time(seconds): 51.9
Ready Queue: 2 3 7 5 4 
process: 2 removed from ready queue at time(seconds): 52.2
Ready Queue: 3 7 5 4 
process: 6 added to ready queue at time(seconds): 52.2
Ready Queue: 3 7 5 4 9 
process: 3 removed from ready queue at time(seconds): 52.5
Ready Queue: 7 5 4 9 
process: 2 added to ready queue at time(seconds): 52.5
Ready Queue: 7 5 4 9 0 
process: 7 removed from ready queue at time(seconds): 52.8
Ready Queue: 5 4 9 0 
process: 3 added to ready queue at time(seconds): 52.8
Ready Queue: 5 4 9 0 1 
process: 5 removed from ready queue at time(seconds): 53.1
Ready Queue: 4 9 0 1 
process: 7 added to ready queue at time(seconds): 53.1
Ready Queue: 4 9 0 1 8 
process: 4 removed from ready queue at time(seconds): 53.4
Ready Queue: 9 0 1 8 
process: 5 added to ready queue at time(seconds): 53.4
Ready Queue: 9 0 1 8 6 
process: 9 removed from ready queue at time(seconds): 53.7
Ready Queue: 0 1 8 6 
process: 4 added to ready queue at time(seconds): 53.7
Ready Queue: 0 1 8 6 2 
process: 0 removed from ready queue at time(seconds): 54
Ready Queue: 1 8 6 2 
process: 9 added to ready queue at time(seconds): 54
Ready Queue: 1 8 6 2 3 
process: 1 removed from ready queue at time(seconds): 54.3
Ready Queue: 8 6 2 3 
process: 0 added to ready queue at time(seconds): 54.3
Ready Queue: 8 6 2 3 7 
process: 8 removed from ready queue at time(seconds): 54.6
Ready Queue: 6 2 3 7 
process: 1 added to ready queue at time(seconds): 54.6
Ready Queue: 6 2 3 7 5 
process: 6 removed from ready queue at time(seconds): 54.9
Ready Queue: 2 3 7 5 
process: 8 added to ready queue at time(seconds): 54.9
Ready Queue: 2 3 7 5 4 
process: 2 removed from ready queue at time(seconds): 55.2
Ready Queue: 3 7 5 4 
process: 6 added to ready queue at time(seconds): 55.2
Ready Queue: 3 7 5 4 9 
process: 3 removed from ready queue at time(seconds): 55.5
Ready Queue: 7 5 4 9 
process: 2 added to ready queue at time(seconds): 55.5
Ready Queue: 7 5 4 9 0 
process: 7 removed from ready queue at time(seconds): 55.8
Ready Queue: 5 4 9 0 
process: 3 added to ready queue at time(seconds): 55.8
Ready Queue: 5 4 9 0 1 
process: 5 removed from ready queue at time(seconds): 56.1
Ready Queue: 4 9 0 1 
process: 7 added to ready queue at time(seconds): 56.1
Ready Queue: 4 9 0 1 8 
process: 4 removed from ready queue at time(seconds): 56.4
Ready Queue: 9 0 1 8 
process: 5 added to ready queue at time(seconds): 56.4
Ready Queue: 9 0 1 8 6 
process: 9 removed from ready queue at time(seconds): 56.7
Ready Queue: 0 1 8 6 
process: 4 added to ready queue at time(seconds): 56.7
Ready Queue: 0 1 8 6 2 
process: 0 removed from ready queue at time(seconds): 56.767
Ready Queue: 1 8 6 2 
process: 9 added to io queue at time(seconds): 56.767
IO Queue: 9 
process: 9 removed from IO queue at time(seconds): 56.767
IO Queue: 
process: 1 removed from ready queue at time(seconds): 57.067
Ready Queue: 8 6 2 3 
process: 0 added to ready queue at time(seconds): 57.067
Ready Queue: 8 6 2 3 
process: 8 removed from ready queue at time(seconds): 57.367
Ready Queue: 6 2 3 7 
process: 1 added to ready queue at time(seconds): 57.367
Ready Queue: 6 2 3 7 
process: 6 removed from ready queue at time(seconds): 57.667
Ready Queue: 2 3 7 5 
process: 8 added to ready queue at time(seconds): 57.667
Ready Queue: 2 3 7 5 
process: 9 added to ready queue at time(seconds): 57.767
Ready Queue: 2 3 7 5 4 
process: 2 removed from ready queue at time(seconds): 57.967
Ready Queue: 3 7 5 4 
process: 6 added to ready queue at time(seconds): 57.967
Ready Queue: 3 7 5 4 0 
process: 3 removed from ready queue at time(seconds): 58.267
Ready Queue: 7 5 4 0 
process: 2 added to ready queue at time(seconds): 58.267
Ready Queue: 7 5 4 0 1 
process: 7 removed from ready queue at time(seconds): 58.567
Ready Queue: 5 4 0 1 
process: 3 added to ready queue at time(seconds): 58.567
Ready Queue: 5 4 0 1 8 
process: 5 removed from ready queue at time(seconds): 58.867
Ready Queue: 4 0 1 8 
process: 7 added to ready queue at time(seconds): 58.867
Ready Queue: 4 0 1 8 9 
process: 4 removed from ready queue at time(seconds): 59.167
Ready Queue: 0 1 8 9 
process: 5 added to ready queue at time(seconds): 59.167
Ready Queue: 0 1 8 9 6 
process: 0 removed from ready queue at time(seconds): 59.467
Ready Queue: 1 8 9 6 
process: 4 added to ready queue at time(seconds): 59.467
Ready Queue: 1 8 9 6 2 
process: 1 removed from ready queue at time(seconds): 59.767
Ready Queue: 8 9 6 2 
process: 0 added to ready queue at time(seconds): 59.767
Ready Queue: 8 9 6 2 3 
process: 8 removed from ready queue at time(seconds): 60.067
Ready Queue: 9 6 2 3 
process: 1 added to ready queue at time(seconds): 60.067
Ready Queue: 9 6 2 3 7 
process: 9 removed from ready queue at time(seconds): 60.367
Ready Queue: 6 2 3 7 
process: 8 added to ready queue at time(seconds): 60.367
Ready Queue: 6 2 3 7 5 
process: 6 removed from ready queue at time(seconds): 60.667
Ready Queue: 2 3 7 5 
process: 9 added to ready queue at time(seconds): 60.667
Ready Queue: 2 3 7 5 4 
process: 2 removed from ready queue at time(seconds): 60.967
Ready Queue: 3 7 5 4 
process: 6 added to ready queue at time(seconds): 60.967
Ready Queue: 3 7 5 4 0 
process: 3 removed from ready queue at time(seconds): 61.267
Ready Queue: 7 5 4 0 
process: 2 added to ready queue at time(seconds): 61.267
Ready Queue: 7 5 4 0 1 
process: 7 removed from ready queue at time(seconds): 61.567
Ready Queue: 5 4 0 1 
process: 3 added to ready queue at time(seconds): 61.567
Ready Queue: 5 4 0 1 8 
process: 5 removed from ready queue at time(seconds): 61.867
Ready Queue: 4 0 1 8 
process: 7 added to ready queue at time(seconds): 61.867
Ready Queue: 4 0 1 8 9 
process: 4 removed from ready queue at time(seconds): 62.167
Ready Queue: 0 1 8 9 
process: 5 added to ready queue at time(seconds): 62.167
Ready Queue: 0 1 8 9 6 
process: 0 removed from ready queue at time(seconds): 62.467
Ready Queue: 1 8 9 6 
process: 4 added to ready queue at time(seconds): 62.467
Ready Queue: 1 8 9 6 2 
process: 1 removed from ready queue at time(seconds): 62.767
Ready Queue: 8 9 6 2 
process: 0 added to ready queue at time(seconds): 62.767
Ready Queue: 8 9 6 2 3 
process: 8 removed from ready queue at time(seconds): 63.067
Ready Queue: 9 6 2 3 
process: 1 added to ready queue at time(seconds): 63.067
Ready Queue: 9 6 2 3 7 
process: 9 removed from ready queue at time(seconds): 63.2245
Ready Queue: 6 2 3 7 
process: 8 added to io queue at time(seconds): 63.2245
IO Queue: 8 
process: 8 removed from IO queue at time(seconds): 63.2245
IO Queue: 
process: 6 removed from ready queue at time(seconds): 63.5245
Ready Queue: 2 3 7 5 
process: 9 added to ready queue at time(seconds): 63.5245
Ready Queue: 2 3 7 5 
process: 2 removed from ready queue at time(seconds): 63.8245
Ready Queue: 3 7 5 4 
process: 6 added to ready queue at time(seconds): 63.8245
Ready Queue: 3 7 5 4 
process: 3 removed from ready queue at time(seconds): 64.1245
Ready Queue: 7 5 4 0 
process: 2 added to ready queue at time(seconds): 64.1245
Ready Queue: 7 5 4 0 
process: 8 added to ready queue at time(seconds): 64.2245
Ready Queue: 7 5 4 0 1 
process: 7 removed from ready queue at time(seconds): 64.4245
Ready Queue: 5 4 0 1 
process: 3 added to ready queue at time(seconds): 64.4245
Ready Queue: 5 4 0 1 9 
process: 5 removed from ready queue at time(seconds): 64.7245
Ready Queue: 4 0 1 9 
process: 7 added to ready queue at time(seconds): 64.7245
Ready Queue: 4 0 1 9 6 
process: 4 removed from ready queue at time(seconds): 65.0245
Ready Queue: 0 1 9 6 
process: 5 added to ready queue at time(seconds): 65.0245
Ready Queue: 0 1 9 6 2 
process: 0 removed from ready queue at time(seconds): 65.3245
Ready Queue: 1 9 6 2 
process: 4 added to ready queue at time(seconds): 65.3245
Ready Queue: 1 9 6 2 8 
process: 1 removed from ready queue at time(seconds): 65.6245
Ready Queue: 9 6 2 8 
process: 0 added to ready queue at time(seconds): 65.6245
Ready Queue: 9 6 2 8 3 
process: 9 removed from ready queue at time(seconds): 65.9245
Ready Queue: 6 2 8 3 
process: 1 added to ready queue at time(seconds): 65.9245
Ready Queue: 6 2 8 3 7 
process: 6 removed from ready queue at time(seconds): 66.2245
Ready Queue: 2 8 3 7 
process: 9 added to ready queue at time(seconds): 66.2245
Ready Queue: 2 8 3 7 5 
process: 2 removed from ready queue at time(seconds): 66.4583
Ready Queue: 8 3 7 5 
process: 6 added to io queue at time(seconds): 66.4583
IO Queue: 6 
process: 6 removed from IO queue at time(seconds): 66.4583
IO Queue: 
process: 8 removed from ready queue at time(seconds): 66.7583
Ready Queue: 3 7 5 4 
process: 2 added to ready queue at time(seconds): 66.7583
Ready Queue: 3 7 5 4 
process: 3 removed from ready queue at time(seconds): 67.0583
Ready Queue: 7 5 4 0 
process: 8 added to ready queue at time(seconds): 67.0583
Ready Queue: 7 5 4 0 
process: 7 removed from ready queue at time(seconds): 67.3583
Ready Queue: 5 4 0 1 
process: 3 added to ready queue at time(seconds): 67.3583
Ready Queue: 5 4 0 1 
process: 6 added to ready queue at time(seconds): 67.4583
Ready Queue: 5 4 0 1 9 
process: 5 removed from ready queue at time(seconds): 67.6583
Ready Queue: 4 0 1 9 
process: 7 added to ready queue at time(seconds): 67.6583
Ready Queue: 4 0 1 9 2 
process: 4 removed from ready queue at time(seconds): 67.9583
Ready Queue: 0 1 9 2 
process: 5 added to ready queue at time(seconds): 67.9583
Ready Queue: 0 1 9 2 8 
process: 0 removed from ready queue at time(seconds): 68.2583
Ready Queue: 1 9 2 8 
process: 4 added to ready queue at time(seconds): 68.2583
Ready Queue: 1 9 2 8 3 
process: 1 removed from ready queue at time(seconds): 68.5583
Ready Queue: 9 2 8 3 
process: 0 added to ready queue at time(seconds): 68.5583
Ready Queue: 9 2 8 3 6 
process: 9 removed from ready queue at time(seconds): 68.8583
Ready Queue: 2 8 3 6 
process: 1 added to ready queue at time(seconds): 68.8583
Ready Queue: 2 8 3 6 7 
process: 2 removed from ready queue at time(seconds): 69.1583
Ready Queue: 8 3 6 7 
process: 9 added to ready queue at time(seconds): 69.1583
Ready Queue: 8 3 6 7 5 
process: 8 removed from ready queue at time(seconds): 69.4583
Ready Queue: 3 6 7 5 
process: 2 added to ready queue at time(seconds): 69.4583
Ready Queue: 3 6 7 5 4 
process: 3 removed from ready queue at time(seconds): 69.7583
Ready Queue: 6 7 5 4 
process: 8 added to ready queue at time(seconds): 69.7583
Ready Queue: 6 7 5 4 0 
process: 6 removed from ready queue at time(seconds): 70.0583
Ready Queue: 7 5 4 0 
process: 3 added to ready queue at time(seconds): 70.0583
Ready Queue: 7 5 4 0 1 
process: 7 removed from ready queue at time(seconds): 70.3583
Ready Queue: 5 4 0 1 
process: 6 added to ready queue at time(seconds): 70.3583
Ready Queue: 5 4 0 1 9 
process: 5 removed from ready queue at time(seconds): 70.3664
Ready Queue: 4 0 1 9 
process: 7 added to io queue at time(seconds): 70.3664
IO Queue: 7 
process: 7 removed from IO queue at time(seconds): 70.3664
IO Queue: 
process: 4 removed from ready queue at time(seconds): 70.6664
Ready Queue: 0 1 9 2 
process: 5 added to ready queue at time(seconds): 70.6664
Ready Queue: 0 1 9 2 
process: 0 removed from ready queue at time(seconds): 70.9664
Ready Queue: 1 9 2 8 
process: 4 added to ready queue at time(seconds): 70.9664
Ready Queue: 1 9 2 8 
process: 1 removed from ready queue at time(seconds): 71.2664
Ready Queue: 9 2 8 3 
process: 0 added to ready queue at time(seconds): 71.2664
Ready Queue: 9 2 8 3 
process: 7 added to ready queue at time(seconds): 71.3664
Ready Queue: 9 2 8 3 6 
process: 9 removed from ready queue at time(seconds): 71.5664
Ready Queue: 2 8 3 6 
process: 1 added to ready queue at time(seconds): 71.5664
Ready Queue: 2 8 3 6 5 
process: 2 removed from ready queue at time(seconds): 71.8664
Ready Queue: 8 3 6 5 
process: 9 added to ready queue at time(seconds): 71.8664
Ready Queue: 8 3 6 5 4 
process: 8 removed from ready queue at time(seconds): 72.1664
Ready Queue: 3 6 5 4 
process: 2 added to ready queue at time(seconds): 72.1664
Ready Queue: 3 6 5 4 0 
process: 3 removed from ready queue at time(seconds): 72.4664
Ready Queue: 6 5 4 0 
process: 8 added to ready queue at time(seconds): 72.4664
Ready Queue: 6 5 4 0 7 
process: 6 removed from ready queue at time(seconds): 72.7664
Ready Queue: 5 4 0 7 
process: 3 added to ready queue at time(seconds): 72.7664
Ready Queue: 5 4 0 7 1 
process: 5 removed from ready queue at time(seconds): 73.0664
Ready Queue: 4 0 7 1 
process: 6 added to ready queue at time(seconds): 73.0664
Ready Queue: 4 0 7 1 9 
process: 4 removed from ready queue at time(seconds): 73.3664
Ready Queue: 0 7 1 9 
process: 5 added to ready queue at time(seconds): 73.3664
Ready Queue: 0 7 1 9 2 
process: 0 removed from ready queue at time(seconds): 73.6664
Ready Queue: 7 1 9 2 
process: 4 added to ready queue at time(seconds): 73.6664
Ready Queue: 7 1 9 2 8 
process: 7 removed from ready queue at time(seconds): 73.9664
Ready Queue: 1 9 2 8 
process: 0 added to ready queue at time(seconds): 73.9664
Ready Queue: 1 9 2 8 3 
process: 1 removed from ready queue at time(seconds): 74.2664
Ready Queue: 9 2 8 3 
process: 7 added to ready queue at time(seconds): 74.2664
Ready Queue: 9 2 8 3 6 
process: 9 removed from ready queue at time(seconds): 74.5664
Ready Queue: 2 8 3 6 
process: 1 added to ready queue at time(seconds): 74.5664
Ready Queue: 2 8 3 6 5 
process: 2 removed from ready queue at time(seconds): 74.8664
Ready Queue: 8 3 6 5 
process: 9 added to ready queue at time(seconds): 74.8664
Ready Queue: 8 3 6 5 4 
process: 8 removed from ready queue at time(seconds): 75.1664
Ready Queue: 3 6 5 4 
process: 2 added to ready queue at time(seconds): 75.1664
Ready Queue: 3 6 5 4 0 
process: 3 removed from ready queue at time(seconds): 75.4664
Ready Queue: 6 5 4 0 
process: 8 added to ready queue at time(seconds): 75.4664
Ready Queue: 6 5 4 0 7 
process: 6 removed from ready queue at time(seconds): 75.7664
Ready Queue: 5 4 0 7 
process: 3 added to ready queue at time(seconds): 75.7664
Ready Queue: 5 4 0 7 1 
process: 5 removed from ready queue at time(seconds): 76.0664
Ready Queue: 4 0 7 1 
process: 6 added to ready queue at time(seconds): 76.0664
Ready Queue: 4 0 7 1 9 
process: 4 removed from ready queue at time(seconds): 76.3214
Ready Queue: 0 7 1 9 
process: 5 added to io queue at time(seconds): 76.3214
IO Queue: 5 
process: 5 removed from IO queue at time(seconds): 76.3214
IO Queue: 
process: 0 removed from ready queue at time(seconds): 76.4219
Ready Queue: 7 1 9 2 
process: 4 added to io queue at time(seconds): 76.4219
IO Queue: 4 
process: 7 removed from ready queue at time(seconds): 76.7219
Ready Queue: 1 9 2 
process: 0 added to ready queue at time(seconds): 76.7219
Ready Queue: 1 9 2 8 
process: 1 removed from ready queue at time(seconds): 77.0219
Ready Queue: 9 2 8 
process: 7 added to ready queue at time(seconds): 77.0219
Ready Queue: 9 2 8 3 
process: 4 removed from IO queue at time(seconds): 77.3214
IO Queue: 
process: 5 added to ready queue at time(seconds): 77.3214
Ready Queue: 9 2 8 3 
process: 9 removed from ready queue at time(seconds): 77.3219
Ready Queue: 2 8 3 6 
process: 1 added to ready queue at time(seconds): 77.3219
Ready Queue: 2 8 3 6 
process: 2 removed from ready queue at time(seconds): 77.6219
Ready Queue: 8 3 6 0 
process: 9 added to ready queue at time(seconds): 77.6219
Ready Queue: 8 3 6 0 
process: 8 removed from ready queue at time(seconds): 77.9219
Ready Queue: 3 6 0 7 
process: 2 added to ready queue at time(seconds): 77.9219
Ready Queue: 3 6 0 7 
process: 3 removed from ready queue at time(seconds): 78.2219
Ready Queue: 6 0 7 5 
process: 8 added to ready queue at time(seconds): 78.2219
Ready Queue: 6 0 7 5 
process: 4 added to ready queue at time(seconds): 78.3214
Ready Queue: 6 0 7 5 1 
process: 6 removed from ready queue at time(seconds): 78.5219
Ready Queue: 0 7 5 1 
process: 3 added to ready queue at time(seconds): 78.5219
Ready Queue: 0 7 5 1 9 
process: 0 removed from ready queue at time(seconds): 78.8219
Ready Queue: 7 5 1 9 
process: 6 added to ready queue at time(seconds): 78.8219
Ready Queue: 7 5 1 9 2 
process: 7 removed from ready queue at time(seconds): 79.1219
Ready Queue: 5 1 9 2 
process: 0 added to ready queue at time(seconds): 79.1219
Ready Queue: 5 1 9 2 8 
process: 5 removed from ready queue at time(seconds): 79.4219
Ready Queue: 1 9 2 8 
process: 7 added to ready queue at time(seconds): 79.4219
Ready Queue: 1 9 2 8 4 
process: 1 removed from ready queue at time(seconds): 79.7219
Ready Queue: 9 2 8 4 
process: 5 added to ready queue at time(seconds): 79.7219
Ready Queue: 9 2 8 4 3 
process: 9 removed from ready queue at time(seconds): 80.0219
Ready Queue: 2 8 4 3 
process: 1 added to ready queue at time(seconds): 80.0219
Ready Queue: 2 8 4 3 6 
process: 2 removed from ready queue at time(seconds): 80.3219
Ready Queue: 8 4 3 6 
process: 9 added to ready queue at time(seconds): 80.3219
Ready Queue: 8 4 3 6 0 
process: 8 removed from ready queue at time(seconds): 80.6219
Ready Queue: 4 3 6 0 
process: 2 added to ready queue at time(seconds): 80.6219
Ready Queue: 4 3 6 0 7 
process: 4 removed from ready queue at time(seconds): 80.9219
Ready Queue: 3 6 0 7 
process: 8 added to ready queue at time(seconds): 80.9219
Ready Queue: 3 6 0 7 5 
process: 3 removed from ready queue at time(seconds): 81.2219
Ready Queue: 6 0 7 5 
process: 4 added to ready queue at time(seconds): 81.2219
Ready Queue: 6 0 7 5 1 
process: 6 removed from ready queue at time(seconds): 81.5219
Ready Queue: 0 7 5 1 
process: 3 added to ready queue at time(seconds): 81.5219
Ready Queue: 0 7 5 1 9 
process: 0 removed from ready queue at time(seconds): 81.8219
Ready Queue: 7 5 1 9 
process: 6 added to ready queue at time(seconds): 81.8219
Ready Queue: 7 5 1 9 2 
process: 7 removed from ready queue at time(seconds): 82.1219
Ready Queue: 5 1 9 2 
process: 0 added to ready queue at time(seconds): 82.1219
Ready Queue: 5 1 9 2 8 
process: 5 removed from ready queue at time(seconds): 82.4219
Ready Queue: 1 9 2 8 
process: 7 added to ready queue at time(seconds): 82.4219
Ready Queue: 1 9 2 8 4 
process: 1 removed from ready queue at time(seconds): 82.7219
Ready Queue: 9 2 8 4 
process: 5 added to ready queue at time(seconds): 82.7219
Ready Queue: 9 2 8 4 3 
process: 9 removed from ready queue at time(seconds): 83.0219
Ready Queue: 2 8 4 3 
process: 1 added to ready queue at time(seconds): 83.0219
Ready Queue: 2 8 4 3 6 
process: 2 removed from ready queue at time(seconds): 83.3219
Ready Queue: 8 4 3 6 
process: 9 added to ready queue at time(seconds): 83.3219
Ready Queue: 8 4 3 6 0 
process: 8 removed from ready queue at time(seconds): 83.6219
Ready Queue: 4 3 6 0 
process: 2 added to ready queue at time(seconds): 83.6219
Ready Queue: 4 3 6 0 7 
process: 4 removed from ready queue at time(seconds): 83.9219
Ready Queue: 3 6 0 7 
process: 8 added to ready queue at time(seconds): 83.9219
Ready Queue: 3 6 0 7 5 
process: 3 removed from ready queue at time(seconds): 84.2219
Ready Queue: 6 0 7 5 
process: 4 added to ready queue at time(seconds): 84.2219
Ready Queue: 6 0 7 5 1 
process: 6 removed from ready queue at time(seconds): 84.3336
Ready Queue: 0 7 5 1 
process: 3 added to io queue at time(seconds): 84.3336
IO Queue: 3 
process: 3 removed from IO queue at time(seconds): 84.3336
IO Queue: 
process: 0 removed from ready queue at time(seconds): 84.6336
Ready Queue: 7 5 1 9 
process: 6 added to ready queue at time(seconds): 84.6336
Ready Queue: 7 5 1 9 
process: 7 removed from ready queue at time(seconds): 84.9336
Ready Queue: 5 1 9 2 
process: 0 added to ready queue at time(seconds): 84.9336
Ready Queue: 5 1 9 2 
process: 5 removed from ready queue at time(seconds): 85.2336
Ready Queue: 1 9 2 8 
process: 7 added to ready queue at time(seconds): 85.2336
Ready Queue: 1 9 2 8 
process: 3 added to ready queue at time(seconds): 85.3336
Ready Queue: 1 9 2 8 4 
process: 1 removed from ready queue at time(seconds): 85.5336
Ready Queue: 9 2 8 4 
process: 5 added to ready queue at time(seconds): 85.5336
Ready Queue: 9 2 8 4 6 
process: 9 removed from ready queue at time(seconds): 85.8336
Ready Queue: 2 8 4 6 
process: 1 added to ready queue at time(seconds): 85.8336
Ready Queue: 2 8 4 6 0 
process: 2 removed from ready queue at time(seconds): 86.1336
Ready Queue: 8 4 6 0 
process: 9 added to ready queue at time(seconds): 86.1336
Ready Queue: 8 4 6 0 7 
process: 8 removed from ready queue at time(seconds): 86.4336
Ready Queue: 4 6 0 7 
process: 2 added to ready queue at time(seconds): 86.4336
Ready Queue: 4 6 0 7 3 
process: 4 removed from ready queue at time(seconds): 86.7336
Ready Queue: 6 0 7 3 
process: 8 added to ready queue at time(seconds): 86.7336
Ready Queue: 6 0 7 3 5 
process: 6 removed from ready queue at time(seconds): 87.0336
Ready Queue: 0 7 3 5 
process: 4 added to ready queue at time(seconds): 87.0336
Ready Queue: 0 7 3 5 1 
process: 0 removed from ready queue at time(seconds): 87.3336
Ready Queue: 7 3 5 1 
process: 6 added to ready queue at time(seconds): 87.3336
Ready Queue: 7 3 5 1 9 
process: 7 removed from ready queue at time(seconds): 87.6336
Ready Queue: 3 5 1 9 
process: 0 added to ready queue at time(seconds): 87.6336
Ready Queue: 3 5 1 9 2 
process: 3 removed from ready queue at time(seconds): 87.9336
Ready Queue: 5 1 9 2 
process: 7 added to ready queue at time(seconds): 87.9336
Ready Queue: 5 1 9 2 8 
process: 5 removed from ready queue at time(seconds): 88.2336
Ready Queue: 1 9 2 8 
process: 3 added to ready queue at time(seconds): 88.2336
Ready Queue: 1 9 2 8 4 
process: 1 removed from ready queue at time(seconds): 88.5336
Ready Queue: 9 2 8 4 
process: 5 added to ready queue at time(seconds): 88.5336
Ready Queue: 9 2 8 4 6 
process: 9 removed from ready queue at time(seconds): 88.8336
Ready Queue: 2 8 4 6 
process: 1 added to ready queue at time(seconds): 88.8336
Ready Queue: 2 8 4 6 0 
process: 2 removed from ready queue at time(seconds): 89.1336
Ready Queue: 8 4 6 0 
process: 9 added to ready queue at time(seconds): 89.1336
Ready Queue: 8 4 6 0 7 
process: 8 removed from ready queue at time(seconds): 89.4336
Ready Queue: 4 6 0 7 
process: 2 added to ready queue at time(seconds): 89.4336
Ready Queue: 4 6 0 7 3 
process: 4 removed from ready queue at time(seconds): 89.7336
Ready Queue: 6 0 7 3 
process: 8 added to ready queue at time(seconds): 89.7336
Ready Queue: 6 0 7 3 5 
process: 6 removed from ready queue at time(seconds): 90.0336
Ready Queue: 0 7 3 5 
process: 4 added to ready queue at time(seconds): 90.0336
Ready Queue: 0 7 3 5 1 
process: 0 removed from ready queue at time(seconds): 90.3336
Ready Queue: 7 3 5 1 
process: 6 added to ready queue at time(seconds): 90.3336
Ready Queue: 7 3 5 1 9 
process: 7 removed from ready queue at time(seconds): 90.6336
Ready Queue: 3 5 1 9 
process: 0 added to ready queue at time(seconds): 90.6336
Ready Queue: 3 5 1 9 2 
process: 3 removed from ready queue at time(seconds): 90.9336
Ready Queue: 5 1 9 2 
process: 7 added to ready queue at time(seconds): 90.9336
Ready Queue: 5 1 9 2 8 
process: 5 removed from ready queue at time(seconds): 91.2336
Ready Queue: 1 9 2 8 
process: 3 added to ready queue at time(seconds): 91.2336
Ready Queue: 1 9 2 8 4 
process: 1 removed from ready queue at time(seconds): 91.5336
Ready Queue: 9 2 8 4 
process: 5 added to ready queue at time(seconds): 91.5336
Ready Queue: 9 2 8 4 6 
process: 9 removed from ready queue at time(seconds): 91.8336
Ready Queue: 2 8 4 6 
process: 1 added to ready queue at time(seconds): 91.8336
Ready Queue: 2 8 4 6 0 
process: 2 removed from ready queue at time(seconds): 92.1336
Ready Queue: 8 4 6 0 
process: 9 added to ready queue at time(seconds): 92.1336
Ready Queue: 8 4 6 0 7 
process: 8 removed from ready queue at time(seconds): 92.4336
Ready Queue: 4 6 0 7 
process: 2 added to ready queue at time(seconds): 92.4336
Ready Queue: 4 6 0 7 3 
process: 4 removed from ready queue at time(seconds): 92.7336
Ready Queue: 6 0 7 3 
process: 8 added to ready queue at time(seconds): 92.7336
Ready Queue: 6 0 7 3 5 
process: 6 removed from ready queue at time(seconds): 93.0336
Ready Queue: 0 7 3 5 
process: 4 added to ready queue at time(seconds): 93.0336
Ready Queue: 0 7 3 5 1 
process: 0 removed from ready queue at time(seconds): 93.3336
Ready Queue: 7 3 5 1 
process: 6 added to ready queue at time(seconds): 93.3336
Ready Queue: 7 3 5 1 9 
process: 7 removed from ready queue at time(seconds): 93.6336
Ready Queue: 3 5 1 9 
process: 0 added to ready queue at time(seconds): 93.6336
Ready Queue: 3 5 1 9 2 
process: 3 removed from ready queue at time(seconds): 93.9336
Ready Queue: 5 1 9 2 
process: 7 added to ready queue at time(seconds): 93.9336
Ready Queue: 5 1 9 2 8 
process: 5 removed from ready queue at time(seconds): 94.2336
Ready Queue: 1 9 2 8 
process: 3 added to ready queue at time(seconds): 94.2336
Ready Queue: 1 9 2 8 4 
process: 1 removed from ready queue at time(seconds): 94.5336
Ready Queue: 9 2 8 4 
process: 5 added to ready queue at time(seconds): 94.5336
Ready Queue: 9 2 8 4 6 
process: 9 removed from ready queue at time(seconds): 94.8336
Ready Queue: 2 8 4 6 
process: 1 added to ready queue at time(seconds): 94.8336
Ready Queue: 2 8 4 6 0 
process: 2 removed from ready queue at time(seconds): 95.1336
Ready Queue: 8 4 6 0 
process: 9 added to ready queue at time(seconds): 95.1336
Ready Queue: 8 4 6 0 7 
process: 8 removed from ready queue at time(seconds): 95.1843
Ready Queue: 4 6 0 7 
process: 2 added to io queue at time(seconds): 95.1843
IO Queue: 2 
process: 2 removed from IO queue at time(seconds): 95.1843
IO Queue: 
process: 4 removed from ready queue at time(seconds): 95.4843
Ready Queue: 6 0 7 3 
process: 8 added to ready queue at time(seconds): 95.4843
Ready Queue: 6 0 7 3 
process: 6 removed from ready queue at time(seconds): 95.7843
Ready Queue: 0 7 3 5 
process: 4 added to ready queue at time(seconds): 95.7843
Ready Queue: 0 7 3 5 
process: 0 removed from ready queue at time(seconds): 96.0843
Ready Queue: 7 3 5 1 
process: 6 added to ready queue at time(seconds): 96.0843
Ready Queue: 7 3 5 1 
process: 2 added to ready queue at time(seconds): 96.1843
Ready Queue: 7 3 5 1 9 
process: 7 removed from ready queue at time(seconds): 96.3843
Ready Queue: 3 5 1 9 
process: 0 added to ready queue at time(seconds): 96.3843
Ready Queue: 3 5 1 9 8 
process: 3 removed from ready queue at time(seconds): 96.6843
Ready Queue: 5 1 9 8 
process: 7 added to ready queue at time(seconds): 96.6843
Ready Queue: 5 1 9 8 4 
process: 5 removed from ready queue at time(seconds): 96.9843
Ready Queue: 1 9 8 4 
process: 3 added to ready queue at time(seconds): 96.9843
Ready Queue: 1 9 8 4 6 
process: 1 removed from ready queue at time(seconds): 97.2843
Ready Queue: 9 8 4 6 
process: 5 added to ready queue at time(seconds): 97.2843
Ready Queue: 9 8 4 6 2 
process: 9 removed from ready queue at time(seconds): 97.5843
Ready Queue: 8 4 6 2 
process: 1 added to ready queue at time(seconds): 97.5843
Ready Queue: 8 4 6 2 0 
process: 8 removed from ready queue at time(seconds): 97.8843
Ready Queue: 4 6 2 0 
process: 9 added to ready queue at time(seconds): 97.8843
Ready Queue: 4 6 2 0 7 
process: 4 removed from ready queue at time(seconds): 98.1843
Ready Queue: 6 2 0 7 
process: 8 added to ready queue at time(seconds): 98.1843
Ready Queue: 6 2 0 7 3 
process: 6 removed from ready queue at time(seconds): 98.4843
Ready Queue: 2 0 7 3 
process: 4 added to ready queue at time(seconds): 98.4843
Ready Queue: 2 0 7 3 5 
process: 2 removed from ready queue at time(seconds): 98.7843
Ready Queue: 0 7 3 5 
process: 6 added to ready queue at time(seconds): 98.7843
Ready Queue: 0 7 3 5 1 
process: 0 removed from ready queue at time(seconds): 99.0843
Ready Queue: 7 3 5 1 
process: 2 added to ready queue at time(seconds): 99.0843
Ready Queue: 7 3 5 1 9 
process: 7 removed from ready queue at time(seconds): 99.3843
Ready Queue: 3 5 1 9 
process: 0 added to ready queue at time(seconds): 99.3843
Ready Queue: 3 5 1 9 8 
process: 3 removed from ready queue at time(seconds): 99.6843
Ready Queue: 5 1 9 8 
process: 7 added to ready queue at time(seconds): 99.6843
Ready Queue: 5 1 9 8 4 
process: 5 removed from ready queue at time(seconds): 99.9843
Ready Queue: 1 9 8 4 
process: 3 added to ready queue at time(seconds): 99.9843
Ready Queue: 1 9 8 4 6 
process: 1 removed from ready queue at time(seconds): 100.284
Ready Queue: 9 8 4 6 
process: 5 added to ready queue at time(seconds): 100.284
Ready Queue: 9 8 4 6 2 
process: 9 removed from ready queue at time(seconds): 100.584
Ready Queue: 8 4 6 2 
process: 1 added to ready queue at time(seconds): 100.584
Ready Queue: 8 4 6 2 0 
process: 8 removed from ready queue at time(seconds): 100.884
Ready Queue: 4 6 2 0 
process: 9 added to ready queue at time(seconds): 100.884
Ready Queue: 4 6 2 0 7 
process: 4 removed from ready queue at time(seconds): 101.184
Ready Queue: 6 2 0 7 
process: 8 added to ready queue at time(seconds): 101.184
Ready Queue: 6 2 0 7 3 
process: 6 removed from ready queue at time(seconds): 101.484
Ready Queue: 2 0 7 3 
process: 4 added to ready queue at time(seconds): 101.484
Ready Queue: 2 0 7 3 5 
process: 2 removed from ready queue at time(seconds): 101.784
Ready Queue: 0 7 3 5 
process: 6 added to ready queue at time(seconds): 101.784
Ready Queue: 0 7 3 5 1 
process: 0 removed from ready queue at time(seconds): 102.084
Ready Queue: 7 3 5 1 
process: 2 added to ready queue at time(seconds): 102.084
Ready Queue: 7 3 5 1 9 
process: 7 removed from ready queue at time(seconds): 102.384
Ready Queue: 3 5 1 9 
process: 0 added to ready queue at time(seconds): 102.384
Ready Queue: 3 5 1 9 8 
process: 3 removed from ready queue at time(seconds): 102.684
Ready Queue: 5 1 9 8 
process: 7 added to ready queue at time(seconds): 102.684
Ready Queue: 5 1 9 8 4 
process: 5 removed from ready queue at time(seconds): 102.984
Ready Queue: 1 9 8 4 
process: 3 added to ready queue at time(seconds): 102.984
Ready Queue: 1 9 8 4 6 
process: 1 removed from ready queue at time(seconds): 103.284
Ready Queue: 9 8 4 6 
process: 5 added to ready queue at time(seconds): 103.284
Ready Queue: 9 8 4 6 2 
process: 9 removed from ready queue at time(seconds): 103.584
Ready Queue: 8 4 6 2 
process: 1 added to ready queue at time(seconds): 103.584
Ready Queue: 8 4 6 2 0 
process: 8 removed from ready queue at time(seconds): 103.884
Ready Queue: 4 6 2 0 
process: 9 added to ready queue at time(seconds): 103.884
Ready Queue: 4 6 2 0 7 
process: 4 removed from ready queue at time(seconds): 104.184
Ready Queue: 6 2 0 7 
process: 8 added to ready queue at time(seconds): 104.184
Ready Queue: 6 2 0 7 3 
process: 6 removed from ready queue at time(seconds): 104.484
Ready Queue: 2 0 7 3 
process: 4 added to ready queue at time(seconds): 104.484
Ready Queue: 2 0 7 3 5 
process: 2 removed from ready queue at time(seconds): 104.784
Ready Queue: 0 7 3 5 
process: 6 added to ready queue at time(seconds): 104.784
Ready Queue: 0 7 3 5 1 
process: 0 removed from ready queue at time(seconds): 105.084
Ready Queue: 7 3 5 1 
process: 2 added to ready queue at time(seconds): 105.084
Ready Queue: 7 3 5 1 9 
process: 7 removed from ready queue at time(seconds): 105.384
Ready Queue: 3 5 1 9 
process: 0 added to ready queue at time(seconds): 105.384
Ready Queue: 3 5 1 9 8 
process: 3 removed from ready queue at time(seconds): 105.684
Ready Queue: 5 1 9 8 
process: 7 added to ready queue at time(seconds): 105.684
Ready Queue: 5 1 9 8 4 
process: 5 removed from ready queue at time(seconds): 105.984
Ready Queue: 1 9 8 4 
process: 3 added to ready queue at time(seconds): 105.984
Ready Queue: 1 9 8 4 6 
process: 1 removed from ready queue at time(seconds): 106.284
Ready Queue: 9 8 4 6 
process: 5 added to ready queue at time(seconds): 106.284
Ready Queue: 9 8 4 6 2 
process: 9 removed from ready queue at time(seconds): 106.584
Ready Queue: 8 4 6 2 
process: 1 added to ready queue at time(seconds): 106.584
Ready Queue: 8 4 6 2 0 
process: 8 removed from ready queue at time(seconds): 106.884
Ready Queue: 4 6 2 0 
process: 9 added to ready queue at time(seconds): 106.884
Ready Queue: 4 6 2 0 7 
process: 4 removed from ready queue at time(seconds): 107.184
Ready Queue: 6 2 0 7 
process: 8 added to ready queue at time(seconds): 107.184
Ready Queue: 6 2 0 7 3 
process: 6 removed from ready queue at time(seconds): 107.484
Ready Queue: 2 0 7 3 
process: 4 added to ready queue at time(seconds): 107.484
Ready Queue: 2 0 7 3 5 
process: 2 removed from ready queue at time(seconds): 107.784
Ready Queue: 0 7 3 5 
process: 6 added to ready queue at time(seconds): 107.784
Ready Queue: 0 7 3 5 1 
process: 0 removed from ready queue at time(seconds): 108.084
Ready Queue: 7 3 5 1 
process: 2 added to ready queue at time(seconds): 108.084
Ready Queue: 7 3 5 1 9 
process: 7 removed from ready queue at time(seconds): 108.384
Ready Queue: 3 5 1 9 
process: 0 added to ready queue at time(seconds): 108.384
Ready Queue: 3 5 1 9 8 
process: 3 removed from ready queue at time(seconds): 108.684
Ready Queue: 5 1 9 8 
process: 7 added to ready queue at time(seconds): 108.684
Ready Queue: 5 1 9 8 4 
process: 5 removed from ready queue at time(seconds): 108.984
Ready Queue: 1 9 8 4 
process: 3 added to ready queue at time(seconds): 108.984
Ready Queue: 1 9 8 4 6 
process: 1 removed from ready queue at time(seconds): 109.284
Ready Queue: 9 8 4 6 
process: 5 added to ready queue at time(seconds): 109.284
Ready Queue: 9 8 4 6 2 
process: 9 removed from ready queue at time(seconds): 109.584
Ready Queue: 8 4 6 2 
process: 1 added to ready queue at time(seconds): 109.584
Ready Queue: 8 4 6 2 0 
process: 8 removed from ready queue at time(seconds): 109.884
Ready Queue: 4 6 2 0 
process: 9 added to ready queue at time(seconds): 109.884
Ready Queue: 4 6 2 0 7 
process: 4 removed from ready queue at time(seconds): 110.184
Ready Queue: 6 2 0 7 
process: 8 added to ready queue at time(seconds): 110.184
Ready Queue: 6 2 0 7 3 
process: 6 removed from ready queue at time(seconds): 110.484
Ready Queue: 2 0 7 3 
process: 4 added to ready queue at time(seconds): 110.484
Ready Queue: 2 0 7 3 5 
process: 2 removed from ready queue at time(seconds): 110.784
Ready Queue: 0 7 3 5 
process: 6 added to ready queue at time(seconds): 110.784
Ready Queue: 0 7 3 5 1 
process: 0 removed from ready queue at time(seconds): 111.084
Ready Queue: 7 3 5 1 
process: 2 added to ready queue at time(seconds): 111.084
Ready Queue: 7 3 5 1 9 
process: 7 removed from ready queue at time(seconds): 111.384
Ready Queue: 3 5 1 9 
process: 0 added to ready queue at time(seconds): 111.384
Ready Queue: 3 5 1 9 8 
process: 3 removed from ready queue at time(seconds): 111.684
Ready Queue: 5 1 9 8 
process: 7 added to ready queue at time(seconds): 111.684
Ready Queue: 5 1 9 8 4 
process: 5 removed from ready queue at time(seconds): 111.984
Ready Queue: 1 9 8 4 
process: 3 added to ready queue at time(seconds): 111.984
Ready Queue: 1 9 8 4 6 
process: 1 removed from ready queue at time(seconds): 112.284
Ready Queue: 9 8 4 6 
process: 5 added to ready queue at time(seconds): 112.284
Ready Queue: 9 8 4 6 2 
process: 9 removed from ready queue at time(seconds): 112.584
Ready Queue: 8 4 6 2 
process: 1 added to ready queue at time(seconds): 112.584
Ready Queue: 8 4 6 2 0 
process: 8 removed from ready queue at time(seconds): 112.651
Ready Queue: 4 6 2 0 
process: 9 added to io queue at time(seconds): 112.651
IO Queue: 9 
process: 9 removed from IO queue at time(seconds): 112.651
IO Queue: 
process: 4 removed from ready queue at time(seconds): 112.951
Ready Queue: 6 2 0 7 
process: 8 added to ready queue at time(seconds): 112.951
Ready Queue: 6 2 0 7 
process: 6 removed from ready queue at time(seconds): 113.251
Ready Queue: 2 0 7 3 
process: 4 added to ready queue at time(seconds): 113.251
Ready Queue: 2 0 7 3 
process: 2 removed from ready queue at time(seconds): 113.551
Ready Queue: 0 7 3 5 
process: 6 added to ready queue at time(seconds): 113.551
Ready Queue: 0 7 3 5 
process: 9 added to ready queue at time(seconds): 113.651
Ready Queue: 0 7 3 5 1 
process: 0 removed from ready queue at time(seconds): 113.851
Ready Queue: 7 3 5 1 
process: 2 added to ready queue at time(seconds): 113.851
Ready Queue: 7 3 5 1 8 
process: 7 removed from ready queue at time(seconds): 114.151
Ready Queue: 3 5 1 8 
process: 0 added to ready queue at time(seconds): 114.151
Ready Queue: 3 5 1 8 4 
process: 3 removed from ready queue at time(seconds): 114.451
Ready Queue: 5 1 8 4 
process: 7 added to ready queue at time(seconds): 114.451
Ready Queue: 5 1 8 4 6 
process: 5 removed from ready queue at time(seconds): 114.751
Ready Queue: 1 8 4 6 
process: 3 added to ready queue at time(seconds): 114.751
Ready Queue: 1 8 4 6 9 
process: 1 removed from ready queue at time(seconds): 115.051
Ready Queue: 8 4 6 9 
process: 5 added to ready queue at time(seconds): 115.051
Ready Queue: 8 4 6 9 2 
process: 8 removed from ready queue at time(seconds): 115.351
Ready Queue: 4 6 9 2 
process: 1 added to ready queue at time(seconds): 115.351
Ready Queue: 4 6 9 2 0 
process: 4 removed from ready queue at time(seconds): 115.651
Ready Queue: 6 9 2 0 
process: 8 added to ready queue at time(seconds): 115.651
Ready Queue: 6 9 2 0 7 
process: 6 removed from ready queue at time(seconds): 115.951
Ready Queue: 9 2 0 7 
process: 4 added to ready queue at time(seconds): 115.951
Ready Queue: 9 2 0 7 3 
process: 9 removed from ready queue at time(seconds): 116.251
Ready Queue: 2 0 7 3 
process: 6 added to ready queue at time(seconds): 116.251
Ready Queue: 2 0 7 3 5 
process: 2 removed from ready queue at time(seconds): 116.551
Ready Queue: 0 7 3 5 
process: 9 added to ready queue at time(seconds): 116.551
Ready Queue: 0 7 3 5 1 
process: 0 removed from ready queue at time(seconds): 116.851
Ready Queue: 7 3 5 1 
process: 2 added to ready queue at time(seconds): 116.851
Ready Queue: 7 3 5 1 8 
process: 7 removed from ready queue at time(seconds): 117.151
Ready Queue: 3 5 1 8 
process: 0 added to ready queue at time(seconds): 117.151
Ready Queue: 3 5 1 8 4 
process: 3 removed from ready queue at time(seconds): 117.451
Ready Queue: 5 1 8 4 
process: 7 added to ready queue at time(seconds): 117.451
Ready Queue: 5 1 8 4 6 
process: 5 removed from ready queue at time(seconds): 117.751
Ready Queue: 1 8 4 6 
process: 3 added to ready queue at time(seconds): 117.751
Ready Queue: 1 8 4 6 9 
process: 1 removed from ready queue at time(seconds): 118.051
Ready Queue: 8 4 6 9 
process: 5 added to ready queue at time(seconds): 118.051
Ready Queue: 8 4 6 9 2 
process: 8 removed from ready queue at time(seconds): 118.351
Ready Queue: 4 6 9 2 
process: 1 added to ready queue at time(seconds): 118.351
Ready Queue: 4 6 9 2 0 
process: 4 removed from ready queue at time(seconds): 118.651
Ready Queue: 6 9 2 0 
process: 8 added to ready queue at time(seconds): 118.651
Ready Queue: 6 9 2 0 7 
process: 6 removed from ready queue at time(seconds): 118.951
Ready Queue: 9 2 0 7 
process: 4 added to ready queue at time(seconds): 118.951
Ready Queue: 9 2 0 7 3 
process: 9 removed from ready queue at time(seconds): 119.251
Ready Queue: 2 0 7 3 
process: 6 added to ready queue at time(seconds): 119.251
Ready Queue: 2 0 7 3 5 
process: 2 removed from ready queue at time(seconds): 119.551
Ready Queue: 0 7 3 5 
process: 9 added to ready queue at time(seconds): 119.551
Ready Queue: 0 7 3 5 1 
process: 0 removed from ready queue at time(seconds): 119.851
Ready Queue: 7 3 5 1 
process: 2 added to ready queue at time(seconds): 119.851
Ready Queue: 7 3 5 1 8 
process: 7 removed from ready queue at time(seconds): 120.151
Ready Queue: 3 5 1 8 
process: 0 added to ready queue at time(seconds): 120.151
Ready Queue: 3 5 1 8 4 
process: 3 removed from ready queue at time(seconds): 120.451
Ready Queue: 5 1 8 4 
process: 7 added to ready queue at time(seconds): 120.451
Ready Queue: 5 1 8 4 6 
process: 5 removed from ready queue at time(seconds): 120.751
Ready Queue: 1 8 4 6 
process: 3 added to ready queue at time(seconds): 120.751
Ready Queue: 1 8 4 6 9 
process: 1 removed from ready queue at time(seconds): 121.051
Ready Queue: 8 4 6 9 
process: 5 added to ready queue at time(seconds): 121.051
Ready Queue: 8 4 6 9 2 
process: 8 removed from ready queue at time(seconds): 121.351
Ready Queue: 4 6 9 2 
process: 1 added to ready queue at time(seconds): 121.351
Ready Queue: 4 6 9 2 0 
process: 4 removed from ready queue at time(seconds): 121.509
Ready Queue: 6 9 2 0 
process: 8 added to io queue at time(seconds): 121.509
IO Queue: 8 
process: 8 removed from IO queue at time(seconds): 121.509
IO Queue: 
process: 6 removed from ready queue at time(seconds): 121.809
Ready Queue: 9 2 0 7 
process: 4 added to ready queue at time(seconds): 121.809
Ready Queue: 9 2 0 7 
process: 9 removed from ready queue at time(seconds): 122.109
Ready Queue: 2 0 7 3 
process: 6 added to ready queue at time(seconds): 122.109
Ready Queue: 2 0 7 3 
process: 2 removed from ready queue at time(seconds): 122.409
Ready Queue: 0 7 3 5 
process: 9 added to ready queue at time(seconds): 122.409
Ready Queue: 0 7 3 5 
process: 8 added to ready queue at time(seconds): 122.509
Ready Queue: 0 7 3 5 1 
process: 0 removed from ready queue at time(seconds): 122.709
Ready Queue: 7 3 5 1 
process: 2 added to ready queue at time(seconds): 122.709
Ready Queue: 7 3 5 1 4 
process: 7 removed from ready queue at time(seconds): 123.009
Ready Queue: 3 5 1 4 
process: 0 added to ready queue at time(seconds): 123.009
Ready Queue: 3 5 1 4 6 
process: 3 removed from ready queue at time(seconds): 123.309
Ready Queue: 5 1 4 6 
process: 7 added to ready queue at time(seconds): 123.309
Ready Queue: 5 1 4 6 9 
process: 5 removed from ready queue at time(seconds): 123.609
Ready Queue: 1 4 6 9 
process: 3 added to ready queue at time(seconds): 123.609
Ready Queue: 1 4 6 9 8 
process: 1 removed from ready queue at time(seconds): 123.909
Ready Queue: 4 6 9 8 
process: 5 added to ready queue at time(seconds): 123.909
Ready Queue: 4 6 9 8 2 
process: 4 removed from ready queue at time(seconds): 123.924
Ready Queue: 6 9 8 2 
process: 1 added to io queue at time(seconds): 123.924
IO Queue: 1 
process: 1 removed from IO queue at time(seconds): 123.924
IO Queue: 
process: 6 removed from ready queue at time(seconds): 124.224
Ready Queue: 9 8 2 0 
process: 4 added to ready queue at time(seconds): 124.224
Ready Queue: 9 8 2 0 
process: 9 removed from ready queue at time(seconds): 124.524
Ready Queue: 8 2 0 7 
process: 6 added to ready queue at time(seconds): 124.524
Ready Queue: 8 2 0 7 
process: 8 removed from ready queue at time(seconds): 124.824
Ready Queue: 2 0 7 3 
process: 9 added to ready queue at time(seconds): 124.824
Ready Queue: 2 0 7 3 
process: 1 added to ready queue at time(seconds): 124.924
Ready Queue: 2 0 7 3 5 
process: 2 removed from ready queue at time(seconds): 125.124
Ready Queue: 0 7 3 5 
process: 8 added to ready queue at time(seconds): 125.124
Ready Queue: 0 7 3 5 4 
process: 0 removed from ready queue at time(seconds): 125.424
Ready Queue: 7 3 5 4 
process: 2 added to ready queue at time(seconds): 125.424
Ready Queue: 7 3 5 4 6 
process: 7 removed from ready queue at time(seconds): 125.591
Ready Queue: 3 5 4 6 
process: 0 added to io queue at time(seconds): 125.591
IO Queue: 0 
process: 0 removed from IO queue at time(seconds): 125.591
IO Queue: 
process: 3 removed from ready queue at time(seconds): 125.891
Ready Queue: 5 4 6 9 
process: 7 added to ready queue at time(seconds): 125.891
Ready Queue: 5 4 6 9 
process: 5 removed from ready queue at time(seconds): 126.191
Ready Queue: 4 6 9 1 
process: 3 added to ready queue at time(seconds): 126.191
Ready Queue: 4 6 9 1 
process: 4 removed from ready queue at time(seconds): 126.491
Ready Queue: 6 9 1 8 
process: 5 added to ready queue at time(seconds): 126.491
Ready Queue: 6 9 1 8 
process: 0 added to ready queue at time(seconds): 126.591
Ready Queue: 6 9 1 8 2 
process: 6 removed from ready queue at time(seconds): 126.791
Ready Queue: 9 1 8 2 
process: 4 added to ready queue at time(seconds): 126.791
Ready Queue: 9 1 8 2 7 
process: 9 removed from ready queue at time(seconds): 127.091
Ready Queue: 1 8 2 7 
process: 6 added to ready queue at time(seconds): 127.091
Ready Queue: 1 8 2 7 3 
process: 1 removed from ready queue at time(seconds): 127.391
Ready Queue: 8 2 7 3 
process: 9 added to ready queue at time(seconds): 127.391
Ready Queue: 8 2 7 3 5 
process: 8 removed from ready queue at time(seconds): 127.691
Ready Queue: 2 7 3 5 
process: 1 added to ready queue at time(seconds): 127.691
Ready Queue: 2 7 3 5 0 
process: 2 removed from ready queue at time(seconds): 127.991
Ready Queue: 7 3 5 0 
process: 8 added to ready queue at time(seconds): 127.991
Ready Queue: 7 3 5 0 4 
process: 7 removed from ready queue at time(seconds): 128.291
Ready Queue: 3 5 0 4 
process: 2 added to ready queue at time(seconds): 128.291
Ready Queue: 3 5 0 4 6 
process: 3 removed from ready queue at time(seconds): 128.591
Ready Queue: 5 0 4 6 
process: 7 added to ready queue at time(seconds): 128.591
Ready Queue: 5 0 4 6 9 
process: 5 removed from ready queue at time(seconds): 128.891
Ready Queue: 0 4 6 9 
process: 3 added to ready queue at time(seconds): 128.891
Ready Queue: 0 4 6 9 1 
process: 0 removed from ready queue at time(seconds): 129.191
Ready Queue: 4 6 9 1 
process: 5 added to ready queue at time(seconds): 129.191
Ready Queue: 4 6 9 1 8 
process: 4 removed from ready queue at time(seconds): 129.491
Ready Queue: 6 9 1 8 
process: 0 added to ready queue at time(seconds): 129.491
Ready Queue: 6 9 1 8 2 
process: 6 removed from ready queue at time(seconds): 129.791
Ready Queue: 9 1 8 2 
process: 4 added to ready queue at time(seconds): 129.791
Ready Queue: 9 1 8 2 7 
process: 9 removed from ready queue at time(seconds): 130.091
Ready Queue: 1 8 2 7 
process: 6 added to ready queue at time(seconds): 130.091
Ready Queue: 1 8 2 7 3 
process: 1 removed from ready queue at time(seconds): 130.391
Ready Queue: 8 2 7 3 
process: 9 added to ready queue at time(seconds): 130.391
Ready Queue: 8 2 7 3 5 
process: 8 removed from ready queue at time(seconds): 130.691
Ready Queue: 2 7 3 5 
process: 1 added to ready queue at time(seconds): 130.691
Ready Queue: 2 7 3 5 0 
process: 2 removed from ready queue at time(seconds): 130.991
Ready Queue: 7 3 5 0 
process: 8 added to ready queue at time(seconds): 130.991
Ready Queue: 7 3 5 0 4 
process: 7 removed from ready queue at time(seconds): 131.291
Ready Queue: 3 5 0 4 
process: 2 added to ready queue at time(seconds): 131.291
Ready Queue: 3 5 0 4 6 
process: 3 removed from ready queue at time(seconds): 131.591
Ready Queue: 5 0 4 6 
process: 7 added to ready queue at time(seconds): 131.591
Ready Queue: 5 0 4 6 9 
process: 5 removed from ready queue at time(seconds): 131.891
Ready Queue: 0 4 6 9 
process: 3 added to ready queue at time(seconds): 131.891
Ready Queue: 0 4 6 9 1 
process: 0 removed from ready queue at time(seconds): 132.191
Ready Queue: 4 6 9 1 
process: 5 added to ready queue at time(seconds): 132.191
Ready Queue: 4 6 9 1 8 
process: 4 removed from ready queue at time(seconds): 132.491
Ready Queue: 6 9 1 8 
process: 0 added to ready queue at time(seconds): 132.491
Ready Queue: 6 9 1 8 2 
process: 6 removed from ready queue at time(seconds): 132.791
Ready Queue: 9 1 8 2 
process: 4 added to ready queue at time(seconds): 132.791
Ready Queue: 9 1 8 2 7 
process: 9 removed from ready queue at time(seconds): 133.025
Ready Queue: 1 8 2 7 
process: 6 added to io queue at time(seconds): 133.025
IO Queue: 6 
process: 6 removed from IO queue at time(seconds): 133.025
IO Queue: 
process: 1 removed from ready queue at time(seconds): 133.325
Ready Queue: 8 2 7 3 
process: 9 added to ready queue at time(seconds): 133.325
Ready Queue: 8 2 7 3 
process: 8 removed from ready queue at time(seconds): 133.625
Ready Queue: 2 7 3 5 
process: 1 added to ready queue at time(seconds): 133.625
Ready Queue: 2 7 3 5 
process: 2 removed from ready queue at time(seconds): 133.925
Ready Queue: 7 3 5 0 
process: 8 added to ready queue at time(seconds): 133.925
Ready Queue: 7 3 5 0 
process: 6 added to ready queue at time(seconds): 134.025
Ready Queue: 7 3 5 0 4 
process: 7 removed from ready queue at time(seconds): 134.225
Ready Queue: 3 5 0 4 
process: 2 added to ready queue at time(seconds): 134.225
Ready Queue: 3 5 0 4 9 
process: 3 removed from ready queue at time(seconds): 134.233
Ready Queue: 5 0 4 9 
process: 7 added to io queue at time(seconds): 134.233
IO Queue: 7 
process: 7 removed from IO queue at time(seconds): 134.233
IO Queue: 
process: 5 removed from ready queue at time(seconds): 134.533
Ready Queue: 0 4 9 1 
process: 3 added to ready queue at time(seconds): 134.533
Ready Queue: 0 4 9 1 
process: 0 removed from ready queue at time(seconds): 134.833
Ready Queue: 4 9 1 8 
process: 5 added to ready queue at time(seconds): 134.833
Ready Queue: 4 9 1 8 
process: 4 removed from ready queue at time(seconds): 135.133
Ready Queue: 9 1 8 6 
process: 0 added to ready queue at time(seconds): 135.133
Ready Queue: 9 1 8 6 
process: 7 added to ready queue at time(seconds): 135.233
Ready Queue: 9 1 8 6 2 
process: 9 removed from ready queue at time(seconds): 135.433
Ready Queue: 1 8 6 2 
process: 4 added to ready queue at time(seconds): 135.433
Ready Queue: 1 8 6 2 3 
process: 1 removed from ready queue at time(seconds): 135.733
Ready Queue: 8 6 2 3 
process: 9 added to ready queue at time(seconds): 135.733
Ready Queue: 8 6 2 3 5 
process: 8 removed from ready queue at time(seconds): 136.033
Ready Queue: 6 2 3 5 
process: 1 added to ready queue at time(seconds): 136.033
Ready Queue: 6 2 3 5 0 
process: 6 removed from ready queue at time(seconds): 136.333
Ready Queue: 2 3 5 0 
process: 8 added to ready queue at time(seconds): 136.333
Ready Queue: 2 3 5 0 7 
process: 2 removed from ready queue at time(seconds): 136.633
Ready Queue: 3 5 0 7 
process: 6 added to ready queue at time(seconds): 136.633
Ready Queue: 3 5 0 7 4 
process: 3 removed from ready queue at time(seconds): 136.933
Ready Queue: 5 0 7 4 
process: 2 added to ready queue at time(seconds): 136.933
Ready Queue: 5 0 7 4 9 
process: 5 removed from ready queue at time(seconds): 137.233
Ready Queue: 0 7 4 9 
process: 3 added to ready queue at time(seconds): 137.233
Ready Queue: 0 7 4 9 1 
process: 0 removed from ready queue at time(seconds): 137.533
Ready Queue: 7 4 9 1 
process: 5 added to ready queue at time(seconds): 137.533
Ready Queue: 7 4 9 1 8 
process: 7 removed from ready queue at time(seconds): 137.833
Ready Queue: 4 9 1 8 
process: 0 added to ready queue at time(seconds): 137.833
Ready Queue: 4 9 1 8 6 
process: 4 removed from ready queue at time(seconds): 138.133
Ready Queue: 9 1 8 6 
process: 7 added to ready queue at time(seconds): 138.133
Ready Queue: 9 1 8 6 2 
process: 9 removed from ready queue at time(seconds): 138.433
Ready Queue: 1 8 6 2 
process: 4 added to ready queue at time(seconds): 138.433
Ready Queue: 1 8 6 2 3 
process: 1 removed from ready queue at time(seconds): 138.733
Ready Queue: 8 6 2 3 
process: 9 added to ready queue at time(seconds): 138.733
Ready Queue: 8 6 2 3 5 
process: 8 removed from ready queue at time(seconds): 139.033
Ready Queue: 6 2 3 5 
process: 1 added to ready queue at time(seconds): 139.033
Ready Queue: 6 2 3 5 0 
process: 6 removed from ready queue at time(seconds): 139.333
Ready Queue: 2 3 5 0 
process: 8 added to ready queue at time(seconds): 139.333
Ready Queue: 2 3 5 0 7 
process: 2 removed from ready queue at time(seconds): 139.633
Ready Queue: 3 5 0 7 
process: 6 added to ready queue at time(seconds): 139.633
Ready Queue: 3 5 0 7 4 
process: 3 removed from ready queue at time(seconds): 139.933
Ready Queue: 5 0 7 4 
process: 2 added to ready queue at time(seconds): 139.933
Ready Queue: 5 0 7 4 9 
process: 5 removed from ready queue at time(seconds): 140.233
Ready Queue: 0 7 4 9 
process: 3 added to ready queue at time(seconds): 140.233
Ready Queue: 0 7 4 9 1 
process: 0 removed from ready queue at time(seconds): 140.533
Ready Queue: 7 4 9 1 
process: 5 added to ready queue at time(seconds): 140.533
Ready Queue: 7 4 9 1 8 
process: 7 removed from ready queue at time(seconds): 140.833
Ready Queue: 4 9 1 8 
process: 0 added to ready queue at time(seconds): 140.833
Ready Queue: 4 9 1 8 6 
process: 4 removed from ready queue at time(seconds): 141.133
Ready Queue: 9 1 8 6 
process: 7 added to ready queue at time(seconds): 141.133
Ready Queue: 9 1 8 6 2 
process: 9 removed from ready queue at time(seconds): 141.433
Ready Queue: 1 8 6 2 
process: 4 added to ready queue at time(seconds): 141.433
Ready Queue: 1 8 6 2 3 
process: 1 removed from ready queue at time(seconds): 141.733
Ready Queue: 8 6 2 3 
process: 9 added to ready queue at time(seconds): 141.733
Ready Queue: 8 6 2 3 5 
process: 8 removed from ready queue at time(seconds): 142.033
Ready Queue: 6 2 3 5 
process: 1 added to ready queue at time(seconds): 142.033
Ready Queue: 6 2 3 5 0 
process: 6 removed from ready queue at time(seconds): 142.333
Ready Queue: 2 3 5 0 
process: 8 added to ready queue at time(seconds): 142.333
Ready Queue: 2 3 5 0 7 
process: 2 removed from ready queue at time(seconds): 142.633
Ready Queue: 3 5 0 7 
process: 6 added to ready queue at time(seconds): 142.633
Ready Queue: 3 5 0 7 4 
process: 3 removed from ready queue at time(seconds): 142.933
Ready Queue: 5 0 7 4 
process: 2 added to ready queue at time(seconds): 142.933
Ready Queue: 5 0 7 4 9 
process: 5 removed from ready queue at time(seconds): 143.233
Ready Queue: 0 7 4 9 
process: 3 added to ready queue at time(seconds): 143.233
Ready Queue: 0 7 4 9 1 
process: 0 removed from ready queue at time(seconds): 143.533
Ready Queue: 7 4 9 1 
process: 5 added to ready queue at time(seconds): 143.533
Ready Queue: 7 4 9 1 8 
process: 7 removed from ready queue at time(seconds): 143.833
Ready Queue: 4 9 1 8 
process: 0 added to ready queue at time(seconds): 143.833
Ready Queue: 4 9 1 8 6 
process: 4 removed from ready queue at time(seconds): 144.133
Ready Queue: 9 1 8 6 
process: 7 added to ready queue at time(seconds): 144.133
Ready Queue: 9 1 8 6 2 
process: 9 removed from ready queue at time(seconds): 144.433
Ready Queue: 1 8 6 2 
process: 4 added to ready queue at time(seconds): 144.433
Ready Queue: 1 8 6 2 3 
process: 1 removed from ready queue at time(seconds): 144.733
Ready Queue: 8 6 2 3 
process: 9 added to ready queue at time(seconds): 144.733
Ready Queue: 8 6 2 3 5 
process: 8 removed from ready queue at time(seconds): 145.033
Ready Queue: 6 2 3 5 
process: 1 added to ready queue at time(seconds): 145.033
Ready Queue: 6 2 3 5 0 
process: 6 removed from ready queue at time(seconds): 145.333
Ready Queue: 2 3 5 0 
process: 8 added to ready queue at time(seconds): 145.333
Ready Queue: 2 3 5 0 7 
process: 2 removed from ready queue at time(seconds): 145.633
Ready Queue: 3 5 0 7 
process: 6 added to ready queue at time(seconds): 145.633
Ready Queue: 3 5 0 7 4 
process: 3 removed from ready queue at time(seconds): 145.933
Ready Queue: 5 0 7 4 
process: 2 added to ready queue at time(seconds): 145.933
Ready Queue: 5 0 7 4 9 
process: 5 removed from ready queue at time(seconds): 146.233
Ready Queue: 0 7 4 9 
process: 3 added to ready queue at time(seconds): 146.233
Ready Queue: 0 7 4 9 1 
process: 0 removed from ready queue at time(seconds): 146.533
Ready Queue: 7 4 9 1 
process: 5 added to ready queue at time(seconds): 146.533
Ready Queue: 7 4 9 1 8 
process: 7 removed from ready queue at time(seconds): 146.833
Ready Queue: 4 9 1 8 
process: 0 added to ready queue at time(seconds): 146.833
Ready Queue: 4 9 1 8 6 
process: 4 removed from ready queue at time(seconds): 147.133
Ready Queue: 9 1 8 6 
process: 7 added to ready queue at time(seconds): 147.133
Ready Queue: 9 1 8 6 2 
process: 9 removed from ready queue at time(seconds): 147.433
Ready Queue: 1 8 6 2 
process: 4 added to ready queue at time(seconds): 147.433
Ready Queue: 1 8 6 2 3 
process: 1 removed from ready queue at time(seconds): 147.733
Ready Queue: 8 6 2 3 
process: 9 added to ready queue at time(seconds): 147.733
Ready Queue: 8 6 2 3 5 
process: 8 removed from ready queue at time(seconds): 148.033
Ready Queue: 6 2 3 5 
process: 1 added to ready queue at time(seconds): 148.033
Ready Queue: 6 2 3 5 0 
process: 6 removed from ready queue at time(seconds): 148.333
Ready Queue: 2 3 5 0 
process: 8 added to ready queue at time(seconds): 148.333
Ready Queue: 2 3 5 0 7 
process: 2 removed from ready queue at time(seconds): 148.633
Ready Queue: 3 5 0 7 
process: 6 added to ready queue at time(seconds): 148.633
Ready Queue: 3 5 0 7 4 
process: 3 removed from ready queue at time(seconds): 148.933
Ready Queue: 5 0 7 4 
process: 2 added to ready queue at time(seconds): 148.933
Ready Queue: 5 0 7 4 9 
process: 5 removed from ready queue at time(seconds): 149.233
Ready Queue: 0 7 4 9 
process: 3 added to ready queue at time(seconds): 149.233
Ready Queue: 0 7 4 9 1 
process: 0 removed from ready queue at time(seconds): 149.488
Ready Queue: 7 4 9 1 
process: 5 added to io queue at time(seconds): 149.488
IO Queue: 5 
process: 5 removed from IO queue at time(seconds): 149.488
IO Queue: 
process: 7 removed from ready queue at time(seconds): 149.788
Ready Queue: 4 9 1 8 
process: 0 added to ready queue at time(seconds): 149.788
Ready Queue: 4 9 1 8 
process: 4 removed from ready queue at time(seconds): 150.088
Ready Queue: 9 1 8 6 
process: 7 added to ready queue at time(seconds): 150.088
Ready Queue: 9 1 8 6 
process: 9 removed from ready queue at time(seconds): 150.388
Ready Queue: 1 8 6 2 
process: 4 added to ready queue at time(seconds): 150.388
Ready Queue: 1 8 6 2 
process: 5 added to ready queue at time(seconds): 150.488
Ready Queue: 1 8 6 2 3 
process: 1 removed from ready queue at time(seconds): 150.688
Ready Queue: 8 6 2 3 
process: 9 added to ready queue at time(seconds): 150.688
Ready Queue: 8 6 2 3 0 
process: 8 removed from ready queue at time(seconds): 150.988
Ready Queue: 6 2 3 0 
process: 1 added to ready queue at time(seconds): 150.988
Ready Queue: 6 2 3 0 7 
process: 6 removed from ready queue at time(seconds): 151.288
Ready Queue: 2 3 0 7 
process: 8 added to ready queue at time(seconds): 151.288
Ready Queue: 2 3 0 7 4 
process: 2 removed from ready queue at time(seconds): 151.588
Ready Queue: 3 0 7 4 
process: 6 added to ready queue at time(seconds): 151.588
Ready Queue: 3 0 7 4 5 
process: 3 removed from ready queue at time(seconds): 151.888
Ready Queue: 0 7 4 5 
process: 2 added to ready queue at time(seconds): 151.888
Ready Queue: 0 7 4 5 9 
process: 0 removed from ready queue at time(seconds): 152.188
Ready Queue: 7 4 5 9 
process: 3 added to ready queue at time(seconds): 152.188
Ready Queue: 7 4 5 9 1 
process: 7 removed from ready queue at time(seconds): 152.488
Ready Queue: 4 5 9 1 
process: 0 added to ready queue at time(seconds): 152.488
Ready Queue: 4 5 9 1 8 
process: 4 removed from ready queue at time(seconds): 152.788
Ready Queue: 5 9 1 8 
process: 7 added to ready queue at time(seconds): 152.788
Ready Queue: 5 9 1 8 6 
process: 5 removed from ready queue at time(seconds): 153.088
Ready Queue: 9 1 8 6 
process: 4 added to ready queue at time(seconds): 153.088
Ready Queue: 9 1 8 6 2 
process: 9 removed from ready queue at time(seconds): 153.388
Ready Queue: 1 8 6 2 
process: 5 added to ready queue at time(seconds): 153.388
Ready Queue: 1 8 6 2 3 
process: 1 removed from ready queue at time(seconds): 153.688
Ready Queue: 8 6 2 3 
process: 9 added to ready queue at time(seconds): 153.688
Ready Queue: 8 6 2 3 0 
process: 8 removed from ready queue at time(seconds): 153.988
Ready Queue: 6 2 3 0 
process: 1 added to ready queue at time(seconds): 153.988
Ready Queue: 6 2 3 0 7 
process: 6 removed from ready queue at time(seconds): 154.288
Ready Queue: 2 3 0 7 
process: 8 added to ready queue at time(seconds): 154.288
Ready Queue: 2 3 0 7 4 
process: 2 removed from ready queue at time(seconds): 154.588
Ready Queue: 3 0 7 4 
process: 6 added to ready queue at time(seconds): 154.588
Ready Queue: 3 0 7 4 5 
process: 3 removed from ready queue at time(seconds): 154.888
Ready Queue: 0 7 4 5 
process: 2 added to ready queue at time(seconds): 154.888
Ready Queue: 0 7 4 5 9 
process: 0 removed from ready queue at time(seconds): 155.188
Ready Queue: 7 4 5 9 
process: 3 added to ready queue at time(seconds): 155.188
Ready Queue: 7 4 5 9 1 
process: 7 removed from ready queue at time(seconds): 155.488
Ready Queue: 4 5 9 1 
process: 0 added to ready queue at time(seconds): 155.488
Ready Queue: 4 5 9 1 8 
process: 4 removed from ready queue at time(seconds): 155.788
Ready Queue: 5 9 1 8 
process: 7 added to ready queue at time(seconds): 155.788
Ready Queue: 5 9 1 8 6 
process: 5 removed from ready queue at time(seconds): 156.088
Ready Queue: 9 1 8 6 
process: 4 added to ready queue at time(seconds): 156.088
Ready Queue: 9 1 8 6 2 
process: 9 removed from ready queue at time(seconds): 156.388
Ready Queue: 1 8 6 2 
process: 5 added to ready queue at time(seconds): 156.388
Ready Queue: 1 8 6 2 3 
process: 1 removed from ready queue at time(seconds): 156.688
Ready Queue: 8 6 2 3 
process: 9 added to ready queue at time(seconds): 156.688
Ready Queue: 8 6 2 3 0 
process: 8 removed from ready queue at time(seconds): 156.988
Ready Queue: 6 2 3 0 
process: 1 added to ready queue at time(seconds): 156.988
Ready Queue: 6 2 3 0 7 
process: 6 removed from ready queue at time(seconds): 157.288
Ready Queue: 2 3 0 7 
process: 8 added to ready queue at time(seconds): 157.288
Ready Queue: 2 3 0 7 4 
process: 2 removed from ready queue at time(seconds): 157.588
Ready Queue: 3 0 7 4 
process: 6 added to ready queue at time(seconds): 157.588
Ready Queue: 3 0 7 4 5 
process: 3 removed from ready queue at time(seconds): 157.888
Ready Queue: 0 7 4 5 
process: 2 added to ready queue at time(seconds): 157.888
Ready Queue: 0 7 4 5 9 
process: 0 removed from ready queue at time(seconds): 158.188
Ready Queue: 7 4 5 9 
process: 3 added to ready queue at time(seconds): 158.188
Ready Queue: 7 4 5 9 1 
process: 7 removed from ready queue at time(seconds): 158.488
Ready Queue: 4 5 9 1 
process: 0 added to ready queue at time(seconds): 158.488
Ready Queue: 4 5 9 1 8 
process: 4 removed from ready queue at time(seconds): 158.788
Ready Queue: 5 9 1 8 
process: 7 added to ready queue at time(seconds): 158.788
Ready Queue: 5 9 1 8 6 
process: 5 removed from ready queue at time(seconds): 158.889
Ready Queue: 9 1 8 6 
process: 4 added to io queue at time(seconds): 158.889
IO Queue: 4 
process: 4 removed from IO queue at time(seconds): 158.889
IO Queue: 
process: 9 removed from ready queue at time(seconds): 159.189
Ready Queue: 1 8 6 2 
process: 5 added to ready queue at time(seconds): 159.189
Ready Queue: 1 8 6 2 
process: 1 removed from ready queue at time(seconds): 159.489
Ready Queue: 8 6 2 3 
process: 9 added to ready queue at time(seconds): 159.489
Ready Queue: 8 6 2 3 
process: 8 removed from ready queue at time(seconds): 159.789
Ready Queue: 6 2 3 0 
process: 1 added to ready queue at time(seconds): 159.789
Ready Queue: 6 2 3 0 
process: 4 added to ready queue at time(seconds): 159.889
Ready Queue: 6 2 3 0 7 
process: 6 removed from ready queue at time(seconds): 160.089
Ready Queue: 2 3 0 7 
process: 8 added to ready queue at time(seconds): 160.089
Ready Queue: 2 3 0 7 5 
process: 2 removed from ready queue at time(seconds): 160.389
Ready Queue: 3 0 7 5 
process: 6 added to ready queue at time(seconds): 160.389
Ready Queue: 3 0 7 5 9 
process: 3 removed from ready queue at time(seconds): 160.689
Ready Queue: 0 7 5 9 
process: 2 added to ready queue at time(seconds): 160.689
Ready Queue: 0 7 5 9 1 
process: 0 removed from ready queue at time(seconds): 160.989
Ready Queue: 7 5 9 1 
process: 3 added to ready queue at time(seconds): 160.989
Ready Queue: 7 5 9 1 4 
process: 7 removed from ready queue at time(seconds): 161.289
Ready Queue: 5 9 1 4 
process: 0 added to ready queue at time(seconds): 161.289
Ready Queue: 5 9 1 4 8 
process: 5 removed from ready queue at time(seconds): 161.589
Ready Queue: 9 1 4 8 
process: 7 added to ready queue at time(seconds): 161.589
Ready Queue: 9 1 4 8 6 
process: 9 removed from ready queue at time(seconds): 161.889
Ready Queue: 1 4 8 6 
process: 5 added to ready queue at time(seconds): 161.889
Ready Queue: 1 4 8 6 2 
process: 1 removed from ready queue at time(seconds): 162.189
Ready Queue: 4 8 6 2 
process: 9 added to ready queue at time(seconds): 162.189
Ready Queue: 4 8 6 2 3 
process: 4 removed from ready queue at time(seconds): 162.489
Ready Queue: 8 6 2 3 
process: 1 added to ready queue at time(seconds): 162.489
Ready Queue: 8 6 2 3 0 
process: 8 removed from ready queue at time(seconds): 162.789
Ready Queue: 6 2 3 0 
process: 4 added to ready queue at time(seconds): 162.789
Ready Queue: 6 2 3 0 7 
process: 6 removed from ready queue at time(seconds): 163.089
Ready Queue: 2 3 0 7 
process: 8 added to ready queue at time(seconds): 163.089
Ready Queue: 2 3 0 7 5 
process: 2 removed from ready queue at time(seconds): 163.389
Ready Queue: 3 0 7 5 
process: 6 added to ready queue at time(seconds): 163.389
Ready Queue: 3 0 7 5 9 
process: 3 removed from ready queue at time(seconds): 163.689
Ready Queue: 0 7 5 9 
process: 2 added to ready queue at time(seconds): 163.689
Ready Queue: 0 7 5 9 1 
process: 0 removed from ready queue at time(seconds): 163.989
Ready Queue: 7 5 9 1 
process: 3 added to ready queue at time(seconds): 163.989
Ready Queue: 7 5 9 1 4 
process: 7 removed from ready queue at time(seconds): 164.289
Ready Queue: 5 9 1 4 
process: 0 added to ready queue at time(seconds): 164.289
Ready Queue: 5 9 1 4 8 
process: 5 removed from ready queue at time(seconds): 164.589
Ready Queue: 9 1 4 8 
process: 7 added to ready queue at time(seconds): 164.589
Ready Queue: 9 1 4 8 6 
process: 9 removed from ready queue at time(seconds): 164.889
Ready Queue: 1 4 8 6 
process: 5 added to ready queue at time(seconds): 164.889
Ready Queue: 1 4 8 6 2 
process: 1 removed from ready queue at time(seconds): 165.189
Ready Queue: 4 8 6 2 
process: 9 added to ready queue at time(seconds): 165.189
Ready Queue: 4 8 6 2 3 
process: 4 removed from ready queue at time(seconds): 165.489
Ready Queue: 8 6 2 3 
process: 1 added to ready queue at time(seconds): 165.489
Ready Queue: 8 6 2 3 0 
process: 8 removed from ready queue at time(seconds): 165.789
Ready Queue: 6 2 3 0 
process: 4 added to ready queue at time(seconds): 165.789
Ready Queue: 6 2 3 0 7 
process: 6 removed from ready queue at time(seconds): 166.089
Ready Queue: 2 3 0 7 
process: 8 added to ready queue at time(seconds): 166.089
Ready Queue: 2 3 0 7 5 
process: 2 removed from ready queue at time(seconds): 166.389
Ready Queue: 3 0 7 5 
process: 6 added to ready queue at time(seconds): 166.389
Ready Queue: 3 0 7 5 9 
process: 3 removed from ready queue at time(seconds): 166.689
Ready Queue: 0 7 5 9 
process: 2 added to ready queue at time(seconds): 166.689
Ready Queue: 0 7 5 9 1 
process: 0 removed from ready queue at time(seconds): 166.989
Ready Queue: 7 5 9 1 
process: 3 added to ready queue at time(seconds): 166.989
Ready Queue: 7 5 9 1 4 
process: 7 removed from ready queue at time(seconds): 167.289
Ready Queue: 5 9 1 4 
process: 0 added to ready queue at time(seconds): 167.289
Ready Queue: 5 9 1 4 8 
process: 5 removed from ready queue at time(seconds): 167.589
Ready Queue: 9 1 4 8 
process: 7 added to ready queue at time(seconds): 167.589
Ready Queue: 9 1 4 8 6 
process: 9 removed from ready queue at time(seconds): 167.889
Ready Queue: 1 4 8 6 
process: 5 added to ready queue at time(seconds): 167.889
Ready Queue: 1 4 8 6 2 
process: 1 removed from ready queue at time(seconds): 167.956
Ready Queue: 4 8 6 2 
process: 9 added to io queue at time(seconds): 167.956
IO Queue: 9 
process: 9 removed from IO queue at time(seconds): 167.956
IO Queue: 
process: 4 removed from ready queue at time(seconds): 168.256
Ready Queue: 8 6 2 3 
process: 1 added to ready queue at time(seconds): 168.256
Ready Queue: 8 6 2 3 
process: 8 removed from ready queue at time(seconds): 168.556
Ready Queue: 6 2 3 0 
process: 4 added to ready queue at time(seconds): 168.556
Ready Queue: 6 2 3 0 
process: 6 removed from ready queue at time(seconds): 168.856
Ready Queue: 2 3 0 7 
process: 8 added to ready queue at time(seconds): 168.856
Ready Queue: 2 3 0 7 
process: 9 added to ready queue at time(seconds): 168.956
Ready Queue: 2 3 0 7 5 
process: 2 removed from ready queue at time(seconds): 169.156
Ready Queue: 3 0 7 5 
process: 6 added to ready queue at time(seconds): 169.156
Ready Queue: 3 0 7 5 1 
process: 3 removed from ready queue at time(seconds): 169.456
Ready Queue: 0 7 5 1 
process: 2 added to ready queue at time(seconds): 169.456
Ready Queue: 0 7 5 1 4 
process: 0 removed from ready queue at time(seconds): 169.756
Ready Queue: 7 5 1 4 
process: 3 added to ready queue at time(seconds): 169.756
Ready Queue: 7 5 1 4 8 
process: 7 removed from ready queue at time(seconds): 170.056
Ready Queue: 5 1 4 8 
process: 0 added to ready queue at time(seconds): 170.056
Ready Queue: 5 1 4 8 9 
process: 5 removed from ready queue at time(seconds): 170.356
Ready Queue: 1 4 8 9 
process: 7 added to ready queue at time(seconds): 170.356
Ready Queue: 1 4 8 9 6 
process: 1 removed from ready queue at time(seconds): 170.656
Ready Queue: 4 8 9 6 
process: 5 added to ready queue at time(seconds): 170.656
Ready Queue: 4 8 9 6 2 
process: 4 removed from ready queue at time(seconds): 170.956
Ready Queue: 8 9 6 2 
process: 1 added to ready queue at time(seconds): 170.956
Ready Queue: 8 9 6 2 3 
process: 8 removed from ready queue at time(seconds): 171.256
Ready Queue: 9 6 2 3 
process: 4 added to ready queue at time(seconds): 171.256
Ready Queue: 9 6 2 3 0 
process: 9 removed from ready queue at time(seconds): 171.556
Ready Queue: 6 2 3 0 
process: 8 added to ready queue at time(seconds): 171.556
Ready Queue: 6 2 3 0 7 
process: 6 removed from ready queue at time(seconds): 171.856
Ready Queue: 2 3 0 7 
